Workbook

Sheet EDIT
A1: PERIODO
A2: ENERO 1
A3: ENERO 2
A4: FEBRERO 1
A5: FEBRERO 2
A6: MARZO 1
A7: MARZO 2
A8: ABRIL 1
A9: ABRIL 2
A10: MAYO 1
A11: MAYO 2
A12: JUNIO 1
... A25: DICIEMBRE 2

Sheet CAPACIDAD
A1: NOMBRE | B1: Rol | C1: % | D1: h reales / persona | E1: Capacidad quincenal | F1: Unidad | G1: FEBRERO 1 | H1: FEBRERO 2 | I1: MARZO 1 | J1: MARZO 2 | K1: ABRIL 1 | L1: ABRIL 2 | M1: MAYO 1 | N1: MAYO 1 | O1: JUNIO 1 | P1: JUNIO 2 | Q1: JULIO 1 | R1: JULIO 2 | S1: AGOSTO 1 | T1: AGOSTO 2 | U1: SEPTIEMBRE 1 | V1: SEPTIEMBRE 2 | W1: OCTUBRE 1 | X1: OCTUBRE 2 | Y1: NOVIEMBRE 1 | Z1: NOVIEMBRE 2 | AA1: DICIEMBRE 1 | AB1: DICIEMBRE 1
A2: ARQ. KARLA MERINO | B2: ARQUITECTO | C2: 0.7 | D2: 80 | E2: =D2*C2 -> 56 | F2: horas/quincenal | G2: 56 | H2: 56 | I2: 28 | J2: 28 | K2: 56 | L2: 56 | M2: 56 | N2: 56 | O2: 56 | P2: 56 | Q2: 56 | R2: 56 | S2: 56 | T2: 56 | U2: 56 | V2: 56 | W2: 56 | X2: 56 | Y2: 56 | Z2: 56 | AA2: 56 | AB2: 56
A3: ARQ. KARLA MERINO | B3: ELECTRICO | C3: 0.3 | D3: 80 | E3: =D3*C3 -> 24 | F3: horas/quincenal | G3: 24 | H3: 24 | I3: 12 | J3: 24 | K3: 24 | L3: 24 | M3: 24 | N3: 24 | O3: 24 | P3: 24 | Q3: 24 | R3: 24 | S3: 24 | T3: 24 | U3: 24 | V3: 24 | W3: 24 | X3: 24 | Y3: 24 | Z3: 24 | AA3: 24 | AB3: 24
A4: ARQ. ANGELO MONTERO | B4: ARQUITECTO | C4: 0.6 | D4: 80 | E4: =D4*C4 -> 48 | F4: horas/quincenal | G4: 56 | H4: 56 | I4: 28 | J4: 48 | K4: 48 | L4: 48 | M4: 48 | N4: 48 | O4: 48 | P4: 48 | Q4: 48 | R4: 48 | S4: 48 | T4: 48 | U4: 48 | V4: 48 | W4: 48 | X4: 48 | Y4: 48 | Z4: 48 | AA4: 48 | AB4: 48
A5: ARQ. ANGELO MONTERO | B5: ELECTRICO | C5: 0.2 | D5: 80 | E5: =D5*C5 -> 16 | F5: horas/quincenal | G5: 24 | H5: 24 | I5: 8 | J5: 16 | K5: 16 | L5: 16 | M5: 16 | N5: 16 | O5: 16 | P5: 16 | Q5: 16 | R5: 16 | S5: 16 | T5: 16 | U5: 16 | V5: 16 | W5: 16 | X5: 16 | Y5: 16 | Z5: 16 | AA5: 16 | AB5: 16
A6: ARQ. ANGELO MONTERO | B6: GAS | C6: 0.2 | D6: 80 | E6: =D6*C6 -> 16 | F6: horas/quincenal | G6: 24 | H6: 24 | I6: 4 | J6: 16 | K6: 16 | L6: 16 | M6: 16 | N6: 16 | O6: 16 | P6: 16 | Q6: 16 | R6: 16 | S6: 16 | T6: 16 | U6: 16 | V6: 16 | W6: 16 | X6: 16 | Y6: 16 | Z6: 16 | AA6: 16 | AB6: 16
A7: ARQ. PIERINA CASALLO | B7: ARQUITECTO | C7: 0.7 | D7: 80 | E7: =D7*C7 -> 56 | F7: horas/quincenal | G7: 56 | H7: 56 | I7: 28 | J7: 56 | K7: 56 | L7: 56 | M7: 56 | N7: 56 | O7: 56 | P7: 56 | Q7: 56 | R7: 56 | S7: 56 | T7: 56 | U7: 56 | V7: 56 | W7: 56 | X7: 56 | Y7: 56 | Z7: 56 | AA7: 56 | AB7: 56
A8: ARQ. PIERINA CASALLO | B8: ELECTRICO | C8: 0.2 | D8: 80 | E8: =D8*C8 -> 16 | F8: horas/quincenal | G8: 56 | H8: 56 | I8: 28 | J8: 56 | K8: 56 | L8: 56 | M8: 56 | N8: 56 | O8: 56 | P8: 56 | Q8: 56 | R8: 56 | S8: 56 | T8: 56 | U8: 56 | V8: 56 | W8: 56 | X8: 56 | Y8: 56 | Z8: 56 | AA8: 56 | AB8: 56
A9: ARQ. PIERINA CASALLO | B9: GAS | C9: 0.1 | D9: 80 | E9: =D9*C9 -> 8 | F9: horas/quincenal | G9: 56 | H9: 56 | I9: 28 | J9: 56 | K9: 56 | L9: 56 | M9: 56 | N9: 56 | O9: 56 | P9: 56 | Q9: 56 | R9: 56 | S9: 56 | T9: 56 | U9: 56 | V9: 56 | W9: 56 | X9: 56 | Y9: 56 | Z9: 56 | AA9: 56 | AB9: 56
A10: ARQ. ALAN TORRES | B10: ARQUITECTO | C10: 0.6 | D10: 80 | E10: =D10*C10 -> 48 | F10: horas/quincenal | G10: 28 | H10: 28 | I10: 14 | J10: 28 | K10: 48 | L10: 48 | M10: 28 | N10: 28 | O10: 28 | P10: 28 | Q10: 28 | R10: 28 | S10: 28 | T10: 28 | U10: 28 | V10: 28 | W10: 28 | X10: 28 | Y10: 28 | Z10: 28 | AA10: 28 | AB10: 28
A11: ARQ. ALAN TORRES | B11: SANITARIO | C11: 0.2 | D11: 80 | E11: =D11*C11 -> 16 | F11: horas/quincenal | K11: 16 | L11: 16 | M11: 16 | N11: 16 | O11: 16 | P11: 16 | Q11: 16 | R11: 16 | S11: 16 | T11: 16 | U11: 16 | V11: 16 | W11: 16 | X11: 16 | Y11: 16 | Z11: 16 | AA11: 16 | AB11: 16
A12: ING. OSCAR MEDALLO | B12: ESTRUCTURAL | C12: 0.6 | D12: 90 | E12: =D12*C12 -> 54 | F12: horas/quincenal | G12: 54 | H12: 54 | I12: 36 | J12: 72 | K12: 72 | L12: 72 | M12: 72 | N12: 72 | O12: 72 | P12: 72 | Q12: 72 | R12: 72 | S12: 72 | T12: 72 | U12: 72 | V12: 72 | W12: 72 | X12: 72 | Y12: 72 | Z12: 72 | AA12: 72 | AB12: 72
A13: ING. OSCAR MEDALLO | B13: SUELOS | C13: 0.2 | D13: 90 | E13: =D13*C13 -> 18 | F13: horas/quincenal | G13: 18 | H13: 18 | I13: 0 | J13: 0 | K13: 0 | L13: 0 | M13: 0 | N13: 0 | O13: 0 | P13: 0 | Q13: 0 | R13: 0 | S13: 0 | T13: 0 | U13: 0 | V13: 0 | W13: 0 | X13: 0 | Y13: 0 | Z13: 0 | AA13: 0 | AB13: 0
A14: ING. OSCAR MEDALLO | B14: ELECTRICO | C14: 0.2 | D14: 90 | E14: =D14*C14 -> 18 | F14: horas/quincenal | G14: 18 | H14: 18 | I14: 9 | J14: 18 | K14: 18 | L14: 18 | M14: 18 | N14: 18 | O14: 18 | P14: 18 | Q14: 18 | R14: 18 | S14: 18 | T14: 18 | U14: 18 | V14: 18 | W14: 18 | X14: 18 | Y14: 18 | Z14: 18 | AA14: 18 | AB14: 18
A15: ING. CRISTIAN HUAMAMANI | B15: ESTRUCTURAL | C15: 0.8 | D15: 80 | E15: =D15*C15 -> 64 | F15: horas/quincenal | G15: 56 | H15: 56 | I15: 40 | J15: 80 | K15: 56 | L15: 56 | M15: 56 | N15: 56 | O15: 56 | P15: 56 | Q15: 56 | R15: 56 | S15: 56 | T15: 56 | U15: 56 | V15: 56 | W15: 56 | X15: 56 | Y15: 56 | Z15: 56 | AA15: 56 | AB15: 56
A16: ING. CRISTIAN HUAMAMANI | B16: SANITARIO | C16: 0.2 | D16: 80 | E16: =D16*C16 -> 16 | F16: horas/quincenal | G16: 24 | H16: 24 | I16: 0 | J16: 0 | K16: 24 | L16: 24 | M16: 24 | N16: 24 | O16: 24 | P16: 24 | Q16: 24 | R16: 24 | S16: 24 | T16: 24 | U16: 24 | V16: 24 | W16: 24 | X16: 24 | Y16: 24 | Z16: 24 | AA16: 24 | AB16: 24
A17: ING. KEVIN DIAZ | B17: SANITARIO | C17: 1 | D17: 80 | E17: =D17*C17 -> 80 | F17: horas/quincenal | G17: 80 | H17: 80 | I17: 40 | J17: 80 | K17: 80 | L17: 80 | M17: 80 | N17: 80 | O17: 80 | P17: 80 | Q17: 80 | R17: 80 | S17: 80 | T17: 80 | U17: 80 | V17: 80 | W17: 80 | X17: 80 | Y17: 80 | Z17: 80 | AA17: 80 | AB17: 80
A18: ING. ROMINA CASALLO | B18: GESTORA | C18: 0.6 | D18: 80 | E18: =D18*C18 -> 48 | F18: horas/quincenal | G18: 48 | H18: 48 | I18: 24 | J18: 48 | K18: 48 | L18: 48 | M18: 48 | N18: 48 | O18: 48 | P18: 48 | Q18: 48 | R18: 48 | S18: 48 | T18: 48 | U18: 48 | V18: 48 | W18: 48 | X18: 48 | Y18: 48 | Z18: 48 | AA18: 48 | AB18: 48
A19: ING. ROMINA CASALLO | B19: SANITARIO | C19: 0.2 | D19: 80 | E19: =D19*C19 -> 16 | F19: horas/quincenal | G19: 16 | H19: 16 | I19: 8 | J19: 16 | K19: 16 | L19: 16 | M19: 16 | N19: 16 | O19: 16 | P19: 16 | Q19: 16 | R19: 16 | S19: 16 | T19: 16 | U19: 16 | V19: 16 | W19: 16 | X19: 16 | Y19: 16 | Z19: 16 | AA19: 16 | AB19: 16
A20: ING. ARON | B20: SUELOS | C20: 0.5 | D20: 40 | E20: =D20*C20 -> 20 | F20: horas/quincenal | G20: 8 | H20: 8 | I20: 16 | J20: 20 | K20: 20 | L20: 20 | M20: 20 | N20: 20 | O20: 20 | P20: 20 | Q20: 20 | R20: 20 | S20: 20 | T20: 20 | U20: 20 | V20: 20 | W20: 20 | X20: 20 | Y20: 20 | Z20: 20 | AA20: 20 | AB20: 20
A21: ING. WILLY MELCHOR | B21: ESTRUCTURAL | C21: 0.4 | D21: 80 | E21: =D21*C21 -> 32 | F21: horas/quincenal | G21: 16 | H21: 16 | I21: 8 | J21: 16 | K21: 16 | L21: 16 | M21: 16 | N21: 16 | O21: 16 | P21: 16 | Q21: 16 | R21: 16 | S21: 16 | T21: 16 | U21: 16 | V21: 16 | W21: 16 | X21: 16 | Y21: 16 | Z21: 16 | AA21: 16 | AB21: 16
A22: TOTAL | E22: =SUM(E2:E21) -> 670 | F22: horas/quincenal | G22: =SUM(G2:G21) -> 718 | H22: =SUM(H2:H21) -> 718 | I22: =SUM(I2:I21) -> 359 | J22: =SUM(J2:J21) -> 678 | K22: =SUM(K2:K21) -> 742 | L22: =SUM(L2:L21) -> 742 | M22: =SUM(M2:M21) -> 722 | N22: =SUM(N2:N21) -> 722 | ... AB22: =SUM(AB2:AB21) -> 722
A23: TOTAL ARQUITECTOS | E23: =SUMIF($B$2:$B$21,"ARQUITECTO",$E$2:$E$21) -> 208 | F23: horas/quincenal | G23: =SUMIF($B$2:$B$21,"ARQUITECTO",G2:G21) -> 196 | H23: =SUMIF($B$2:$B$21,"ARQUITECTO",H2:H21) -> 196 | I23: =SUMIF($B$2:$B$21,"ARQUITECTO",I2:I21) -> 98 | J23: =SUMIF($B$2:$B$21,"ARQUITECTO",J2:J21) -> 160 | K23: =SUMIF($B$2:$B$21,"ARQUITECTO",K2:K21) -> 208 | L23: =SUMIF($B$2:$B$21,"ARQUITECTO",L2:L21) -> 208 | M23: =SUMIF($B$2:$B$21,"ARQUITECTO",M2:M21) -> 188 | N23: =SUMIF($B$2:$B$21,"ARQUITECTO",N2:N21) -> 188 | ... AB23: =SUMIF($B$2:$B$21,"ARQUITECTO",AB2:AB21) -> 188
A24: TOTAL ESTRUCTURALES | E24: =SUMIF($B$2:$B$21,"ESTRUCTURAL",$E$2:$E$21) -> 150 | F24: horas/quincenal | G24: =SUMIF($B$2:$B$21,"ESTRUCTURAL",G2:G21) -> 126 | H24: =SUMIF($B$2:$B$21,"ESTRUCTURAL",H2:H21) -> 126 | I24: =SUMIF($B$2:$B$21,"ESTRUCTURAL",I2:I21) -> 84 | J24: =SUMIF($B$2:$B$21,"ESTRUCTURAL",J2:J21) -> 168 | K24: =SUMIF($B$2:$B$21,"ESTRUCTURAL",K2:K21) -> 144 | L24: =SUMIF($B$2:$B$21,"ESTRUCTURAL",L2:L21) -> 144 | M24: =SUMIF($B$2:$B$21,"ESTRUCTURAL",M2:M21) -> 144 | N24: =SUMIF($B$2:$B$21,"ESTRUCTURAL",N2:N21) -> 144 | ... AB24: =SUMIF($B$2:$B$21,"ESTRUCTURAL",AB2:AB21) -> 144
A25: SUELOS | E25: =SUMIF($B$2:$B$21,"SUELOS",$E$2:$E$21) -> 38 | F25: horas/quincenal | G25: =SUMIF($B$2:$B$21,"SUELOS",G2:G21) -> 26 | H25: =SUMIF($B$2:$B$21,"SUELOS",H2:H21) -> 26 | I25: =SUMIF($B$2:$B$21,"SUELOS",I2:I21) -> 16 | J25: =SUMIF($B$2:$B$21,"SUELOS",J2:J21) -> 20 | K25: =SUMIF($B$2:$B$21,"SUELOS",K2:K21) -> 20 | L25: =SUMIF($B$2:$B$21,"SUELOS",L2:L21) -> 20 | M25: =SUMIF($B$2:$B$21,"SUELOS",M2:M21) -> 20 | N25: =SUMIF($B$2:$B$21,"SUELOS",N2:N21) -> 20 | ... AA25: =SUMIF($B$2:$B$21,"SUELOS",AA2:AA21) -> 20 | AB25: =SUMIF($B$2:$B$21,"SUELOS",Z2:Z21) -> 20
A26: TOTAL SANITARIOS | E26: =SUMIF($B$2:$B$21,"SANITARIO",$E$2:$E$21) -> 128 | F26: horas/quincenal | G26: =SUMIF($B$2:$B$21,"SANITARIO",G2:G21) -> 120 | H26: =SUMIF($B$2:$B$21,"SANITARIO",H2:H21) -> 120 | I26: =SUMIF($B$2:$B$21,"SANITARIO",I2:I21) -> 48 | J26: =SUMIF($B$2:$B$21,"SANITARIO",J2:J21) -> 96 | K26: =SUMIF($B$2:$B$21,"SANITARIO",K2:K21) -> 136 | L26: =SUMIF($B$2:$B$21,"SANITARIO",L2:L21) -> 136 | M26: =SUMIF($B$2:$B$21,"SANITARIO",M2:M21) -> 136 | N26: =SUMIF($B$2:$B$21,"SANITARIO",N2:N21) -> 136 | ... AB26: =SUMIF($B$2:$B$21,"SANITARIO",AB2:AB21) -> 136
A27: TOTAL ELECTRICOS | E27: =SUMIF($B$2:$B$21,"ELECTRICO",$E$2:$E$21) -> 74 | F27: horas/quincenal | G27: =SUMIF($B$2:$B$21,"ELECTRICO",G2:G21) -> 122 | H27: =SUMIF($B$2:$B$21,"ELECTRICO",H2:H21) -> 122 | I27: =SUMIF($B$2:$B$21,"ELECTRICO",I2:I21) -> 57 | J27: =SUMIF($B$2:$B$21,"ELECTRICO",J2:J21) -> 114 | K27: =SUMIF($B$2:$B$21,"ELECTRICO",K2:K21) -> 114 | L27: =SUMIF($B$2:$B$21,"ELECTRICO",L2:L21) -> 114 | M27: =SUMIF($B$2:$B$21,"ELECTRICO",M2:M21) -> 114 | N27: =SUMIF($B$2:$B$21,"ELECTRICO",N2:N21) -> 114 | ... AB27: =SUMIF($B$2:$B$21,"ELECTRICO",AB2:AB21) -> 114
A28: TOTAL GAS | E28: =SUMIF($B$2:$B$21,"GAS",$E$2:$E$21) -> 24 | F28: horas/quincenal | G28: =SUMIF($B$2:$B$21,"GAS",G2:G21) -> 80 | H28: =SUMIF($B$2:$B$21,"GAS",H2:H21) -> 80 | I28: =SUMIF($B$2:$B$21,"GAS",I2:I21) -> 32 | J28: =SUMIF($B$2:$B$21,"GAS",J2:J21) -> 72 | K28: =SUMIF($B$2:$B$21,"GAS",K2:K21) -> 72 | L28: =SUMIF($B$2:$B$21,"GAS",L2:L21) -> 72 | M28: =SUMIF($B$2:$B$21,"GAS",M2:M21) -> 72 | N28: =SUMIF($B$2:$B$21,"GAS",N2:N21) -> 72 | ... AB28: =SUMIF($B$2:$B$21,"GAS",AB2:AB21) -> 72
A29: GESTIÓN | E29: =SUMIF($B$2:$B$21,"GESTORA",$E$2:$E$21) -> 48 | F29: horas/quincenal | G29: =SUMIF($B$2:$B$21,"GESTORA",G2:G21) -> 48 | H29: =SUMIF($B$2:$B$21,"GESTORA",H2:H21) -> 48 | I29: =SUMIF($B$2:$B$21,"GESTORA",I2:I21) -> 24 | J29: =SUMIF($B$2:$B$21,"GESTORA",J2:J21) -> 48 | K29: =SUMIF($B$2:$B$21,"GESTORA",K2:K21) -> 48 | L29: =SUMIF($B$2:$B$21,"GESTORA",L2:L21) -> 48 | M29: =SUMIF($B$2:$B$21,"GESTORA",M2:M21) -> 48 | N29: =SUMIF($B$2:$B$21,"GESTORA",N2:N21) -> 48 | ... AB29: =SUMIF($B$2:$B$21,"GESTORA",AB2:AB21) -> 48

Sheet MH-DFM4-0226-Pueblo Libre-Silvi
A1: NOMBRE DE PROYECTO | B1: TIPO DE EXPEDIENTE | C1: ESPECIALIDAD | D1: PARTIDA | E1: VERSION | F1: HORAS CALENDARIO TECNICOS LABORADOS PARA PERSONA CON RENDIMIENTO AL 100% | G1: HORAS CALENDARIO EN REUNIONES CON CLIENTES PARA PERSONA CON RENDIMIENTO AL 100% | H1: TOTAL | I1: HORAS ADICIONALES | J1: TOTAL HORAS RESTANTES | K1: Column11
A2: DF+IM4 - 0226 - Pueblo Libre - Sílvia & Eduardo | B2: Declaratoria + Independización | C2: ARQUITECTURA | D2: TAREAS ADMINISTRATIVAS - Subir DNI al DRIVE | E2: V 0.0 - INICIO DEL PROYECTO | F2: 0 | H2: 0 | J2: 0 | K2: OK
A3: DF+IM4 - 0226 - Pueblo Libre - Sílvia & Eduardo | B3: Declaratoria + Independización | C3: ARQUITECTURA | D3: ARQUITECTURA - Digitalización de planos | E3: V 2.0 - PRELIMINAR A ENTREGA A SUNARP | F3: 6 | H3: 6 | I3: 2 | J3: 0 | K3: OK
A4: DF+IM4 - 0226 - Pueblo Libre - Sílvia & Eduardo | B4: Declaratoria + Independización | C4: ARQUITECTURA | D4: ARQUITECTURA - Planos de independización | E4: V 2.0 - PRELIMINAR A ENTREGA A SUNARP | F4: 4 | H4: 4 | J4: 4 | K4: OK
A5: DF+IM4 - 0226 - Pueblo Libre - Sílvia & Eduardo | B5: Declaratoria + Independización | C5: ARQUITECTURA | D5: ARQUITECTURA - Plano de Ubicación y Localización | E5: V 2.0 - PRELIMINAR A ENTREGA A SUNARP | F5: 3 | H5: 3 | J5: 0 | K5: OK
A6: DF+IM4 - 0226 - Pueblo Libre - Sílvia & Eduardo | B6: Declaratoria + Independización | C6: ARQUITECTURA | D6: ARQUITECTURA - Cuadro de áreas a declarar | E6: V 2.0 - PRELIMINAR A ENTREGA A SUNARP | F6: 1 | H6: 1 | J6: 1 | K6: OK
A7: DF+IM4 - 0226 - Pueblo Libre - Sílvia & Eduardo | B7: Declaratoria + Independización | C7: ARQUITECTURA | D7: ARQUITECTURA - Formularios FOR | E7: V 2.0 - PRELIMINAR A ENTREGA A SUNARP | F7: 3 | H7: 3 | I7: -2.5 | J7: 0 | K7: OK
A8: DF+IM4 - 0226 - Pueblo Libre - Sílvia & Eduardo | B8: Declaratoria + Independización | C8: ARQUITECTURA | D8: ARQUITECTURA - Declaración jurada no improcedencia | E8: V 2.0 - PRELIMINAR A ENTREGA A SUNARP | F8: 0.5 | H8: 0.5 | I8: 0 | J8: 0 | K8: OK
A9: DF+IM4 - 0226 - Pueblo Libre - Sílvia & Eduardo | B9: Declaratoria + Independización | C9: ARQUITECTURA | D9: ARQUITECTURA - Informe técnica del verificador (ITF) | E9: V 2.0 - PRELIMINAR A ENTREGA A SUNARP | F9: 2 | H9: 2 | I9: -1.5 | J9: 0 | K9: OK
A10: DF+IM4 - 0226 - Pueblo Libre - Sílvia & Eduardo | B10: Declaratoria + Independización | C10: ARQUITECTURA | D10: ARQUITECTURA - Anexo 1 | E10: V 2.0 - PRELIMINAR A ENTREGA A SUNARP | F10: 2 | H10: 2 | J10: 2 | K10: OK
A11: DF+IM4 - 0226 - Pueblo Libre - Sílvia & Eduardo | B11: Declaratoria + Independización | C11: ARQUITECTURA | D11: ARQUITECTURA - Memoria descriptiva de declaratoria de fábrica | E11: V 2.0 - PRELIMINAR A ENTREGA A SUNARP | F11: 1 | H11: 1 | J11: 1 | K11: OK
A12: DF+IM4 - 0226 - Pueblo Libre - Sílvia & Eduardo | B12: Declaratoria + Independización | C12: ARQUITECTURA | D12: ARQUITECTURA - Reunión para exponer a cliente | E12: V 2.0 - PRELIMINAR A ENTREGA A SUNARP | F12: 0 | G12: 2 | H12: 2 | J12: 2 | K12: OK
A13: DF+IM4 - 0226 - Pueblo Libre - Sílvia & Eduardo | B13: Declaratoria + Independización | C13: ARQUITECTURA | D13: TAREAS ADMINISTRATIVAS - MANDAR A IMPRENTA 1 JUEGO DE EXPEDIENTE A PLOTEAR | E13: V 2.0 - PRELIMINAR A ENTREGA A SUNARP | F13: 1 | H13: 1 | J13: 1 | K13: OK
A14: DF+IM4 - 0226 - Pueblo Libre - Sílvia & Eduardo | B14: Declaratoria + Independización | C14: ARQUITECTURA | D14: TAREAS ADMINISTRATIVAS - SACAR 2 JUEGOS DE COPIA DEL EXPEDIENTE | E14: V 2.0 - PRELIMINAR A ENTREGA A SUNARP | F14: 1 | H14: 1 | J14: 1 | K14: OK
A15: DF+IM4 - 0226 - Pueblo Libre - Sílvia & Eduardo | B15: Declaratoria + Independización | C15: ARQUITECTURA | D15: ARQUITECTURA - Revisión de SUNARP | E15: V 2.1 - ENTREGA TÉCNICA FINAL DE EXPEDIENTE A REVISORES | F15: 0 | H15: 0 | J15: 0 | K15: OK
A16: DF+IM4 - 0226 - Pueblo Libre - Sílvia & Eduardo | B16: Declaratoria + Independización | C16: ARQUITECTURA | D16: ARQUITECTURA - Lev. de Observaciones de SUNARP | E16: V 2.0 - PRELIMINAR A ENTREGA A SUNARP | F16: 5 | H16: 5 | J16: 5 | K16: OK
A17: DF+IM4 - 0226 - Pueblo Libre - Sílvia & Eduardo | B17: Declaratoria + Independización | C17: ARQUITECTURA | D17: TAREAS ADMINISTRATIVAS - EMISIÓN DE DECLARATORIA DE FÁBRICA | E17: V 2.0 - PRELIMINAR A ENTREGA A SUNARP | F17: 0 | H17: 0 | J17: 0 | K17: OK
A18: DF+IM4 - 0226 - Pueblo Libre - Sílvia & Eduardo | B18: Declaratoria + Independización | C18: GESTIÓN Y ADMINISTRACIÓN | D18: TAREAS ADMINISTRATIVAS - Crear grupo de WPS con cliente y equipo | E18: V 0.0 - INICIO DEL PROYECTO | F18: 0 | H18: 0 | J18: 0 | K18: OK
A19: DF+IM4 - 0226 - Pueblo Libre - Sílvia & Eduardo | B19: Declaratoria + Independización | C19: GESTIÓN Y ADMINISTRACIÓN | D19: TAREAS ADMINISTRATIVAS - Crear DRIVE del proyecto | E19: V 0.0 - INICIO DEL PROYECTO | F19: 0 | H19: 0 | J19: 0 | K19: OK
A20: DF+IM4 - 0226 - Pueblo Libre - Sílvia & Eduardo | B20: Declaratoria + Independización | C20: GESTIÓN Y ADMINISTRACIÓN | D20: TAREAS ADMINISTRATIVAS - Coordinar dia y hora para realizar levantamiento arquitectónico | E20: V 0.0 - INICIO DEL PROYECTO | F20: 0 | H20: 0 | J20: 0 | K20: OK
A21: DF+IM4 - 0226 - Pueblo Libre - Sílvia & Eduardo | B21: Declaratoria + Independización | C21: GESTIÓN Y ADMINISTRACIÓN | D21: TAREAS ADMINISTRATIVAS - Realizar levantamiento arquitectónico | E21: V 0.0 - INICIO DEL PROYECTO | F21: 0 | H21: 0 | J21: 0 | K21: OK

Sheet MP-0525 - Surco - Arq  Edin
A1: NOMBRE DE PROYECTO | B1: TIPO DE EXPEDIENTE | C1: ESPECIALIDAD | D1: PARTIDA | E1: VERSION | F1: HORAS CALENDARIO TECNICOS LABORADOS PARA PERSONA CON RENDIMIENTO AL 100% | G1: HORAS CALENDARIO EN REUNIONES CON CLIENTES PARA PERSONA CON RENDIMIENTO AL 100% | H1: TOTAL | I1: HORAS ADICIONALES | J1: TOTAL HORAS RESTANTES | K1: Column11
A2: LNM7 - 0525 - Surco - Arq. Edinson Rufasto | B2: Exp. Licencia mod. B | C2: ARQUITECTURA | D2: ARQUITECTURA - Propuesta de render 3D | E2: V 4.0 - PRELIMINAR A ENTREGA DEL EXPEDIENTE A MUNICIPALIDAD | F2: 23 | H2: 23 | I2: 52 | J2: 0 | K2: OK
A3: LNM7 - 0525 - Surco - Arq. Edinson Rufasto | B3: Exp. Licencia mod. B | C3: ARQUITECTURA | D3: ARQUITECTURA - Reunión con cliente para ver render 3D | E3: V 4.0 - PRELIMINAR A ENTREGA DEL EXPEDIENTE A MUNICIPALIDAD | F3: 0 | G3: 6 | H3: 6 | J3: 4.5 | K3: OK
A4: LNM7 - 0525 - Surco - Arq. Edinson Rufasto | B4: Exp. Licencia mod. B | C4: ARQUITECTURA | D4: TAREAS ADMINISTRATIVAS - Corroborar bloque actualizado en todas las especialidades | E4: V 3.0 - PRELIMINAR A ENTREGA DEL EXPEDIENTE A REVISORES URBANOS | F4: 4 | H4: 4 | J4: 2 | K4: OK
A5: LNM7 - 0525 - Surco - Arq. Edinson Rufasto | B5: Exp. Licencia mod. B | C5: ARQUITECTURA | D5: TAREAS ADMINISTRATIVAS - MANDAR A IMPRENTA PLANOS A PLOTEAR | E5: V 4.0 - PRELIMINAR A ENTREGA DEL EXPEDIENTE A MUNICIPALIDAD | F5: 0 | H5: 0 | J5: 0 | K5: OK
A6: LNM7 - 0525 - Surco - Arq. Edinson Rufasto | B6: Exp. Licencia mod. B | C6: ARQUITECTURA | D6: TAREAS ADMINISTRATIVAS - Firmar y sellar expediente por revisores urbanos | E6: V 4.0 - PRELIMINAR A ENTREGA DEL EXPEDIENTE A MUNICIPALIDAD | F6: 0 | H6: 0 | J6: 0 | K6: OK
A7: LNM7 - 0525 - Surco - Arq. Edinson Rufasto | B7: Exp. Licencia mod. B | C7: ARQUITECTURA | D7: TAREAS ADMINISTRATIVAS - Recoger expediente firmado y sellado de REVISORES URBANOS | E7: V 4.0 - PRELIMINAR A ENTREGA DEL EXPEDIENTE A MUNICIPALIDAD | F7: 0 | H7: 0 | J7: 0 | K7: OK
A8: LNM7 - 0525 - Surco - Arq. Edinson Rufasto | B8: Exp. Licencia mod. B | C8: ARQUITECTURA | D8: TAREAS ADMINISTRATIVAS - Entrega de expediente impreso a cliente | E8: V 4.0 - PRELIMINAR A ENTREGA DEL EXPEDIENTE A MUNICIPALIDAD | F8: 0 | H8: 0 | J8: 0 | K8: OK
A9: LNM7 - 0525 - Surco - Arq. Edinson Rufasto | B9: Exp. Licencia mod. B | C9: ARQUITECTURA | D9: ARQUITECTURA - Revisión por Muni | E9: V 4.1 - ENTREGA DEL EXPEDIENTE A MUNICIPALIDAD | F9: 0 | H9: 0 | J9: 0 | K9: OK
A10: LNM7 - 0525 - Surco - Arq. Edinson Rufasto | B10: Exp. Licencia mod. B | C10: ESTRUCTURAS | D10: ESTRUCTURAS - Propuesta estructural de columnas, placas y vigas | E10: V 3.0 - PRELIMINAR A ENTREGA DEL EXPEDIENTE A REVISORES URBANOS | F10: 2 | H10: 2 | I10: 14 | J10: 0 | K10: OK
A11: LNM7 - 0525 - Surco - Arq. Edinson Rufasto | B11: Exp. Licencia mod. B | C11: ESTRUCTURAS | D11: ESTRUCTURAS - Modelado de estructuras | E11: V 3.0 - PRELIMINAR A ENTREGA DEL EXPEDIENTE A REVISORES URBANOS | F11: 7 | H11: 7 | I11: 3 | J11: 0 | K11: OK
A12: LNM7 - 0525 - Surco - Arq. Edinson Rufasto | B12: Exp. Licencia mod. B | C12: ESTRUCTURAS | D12: TAREAS ADMINISTRATIVAS - Junta de ingenierías | E12: V 3.0 - PRELIMINAR A ENTREGA DEL EXPEDIENTE A REVISORES URBANOS | F12: 2 | H12: 2 | I12: -2 | J12: 0 | K12: OK
A13: LNM7 - 0525 - Surco - Arq. Edinson Rufasto | B13: Exp. Licencia mod. B | C13: ESTRUCTURAS | D13: ESTRUCTURAS - Planos de encofrados de techos | E13: V 3.0 - PRELIMINAR A ENTREGA DEL EXPEDIENTE A REVISORES URBANOS | F13: 5 | H13: 5 | I13: 3 | J13: 0 | K13: OK
A14: LNM7 - 0525 - Surco - Arq. Edinson Rufasto | B14: Exp. Licencia mod. B | C14: ESTRUCTURAS | D14: ESTRUCTURAS - Cuadro de columnas | E14: V 3.0 - PRELIMINAR A ENTREGA DEL EXPEDIENTE A REVISORES URBANOS | F14: 2 | H14: 2 | J14: 0 | K14: OK
A15: LNM7 - 0525 - Surco - Arq. Edinson Rufasto | B15: Exp. Licencia mod. B | C15: ESTRUCTURAS | D15: ESTRUCTURAS - Desarrollo de vigas | E15: V 3.0 - PRELIMINAR A ENTREGA DEL EXPEDIENTE A REVISORES URBANOS | F15: 4 | H15: 4 | J15: 0 | K15: OK
A16: LNM7 - 0525 - Surco - Arq. Edinson Rufasto | B16: Exp. Licencia mod. B | C16: ESTRUCTURAS | D16: ESTRUCTURAS - Detalle de placas | E16: V 3.0 - PRELIMINAR A ENTREGA DEL EXPEDIENTE A REVISORES URBANOS | F16: 4 | H16: 4 | J16: 0 | K16: OK
A17: LNM7 - 0525 - Surco - Arq. Edinson Rufasto | B17: Exp. Licencia mod. B | C17: ESTRUCTURAS | D17: ESTRUCTURAS - Planos de cimentación | E17: V 3.0 - PRELIMINAR A ENTREGA DEL EXPEDIENTE A REVISORES URBANOS | F17: 5 | H17: 5 | J17: 0 | K17: OK
A18: LNM7 - 0525 - Surco - Arq. Edinson Rufasto | B18: Exp. Licencia mod. B | C18: ESTRUCTURAS | D18: ESTRUCTURAS - Cortes de cimentación | E18: V 3.0 - PRELIMINAR A ENTREGA DEL EXPEDIENTE A REVISORES URBANOS | F18: 3 | H18: 3 | J18: 0 | K18: OK
A19: LNM7 - 0525 - Surco - Arq. Edinson Rufasto | B19: Exp. Licencia mod. B | C19: ESTRUCTURAS | D19: ESTRUCTURAS - Corte de muros de sótanos | E19: V 3.0 - PRELIMINAR A ENTREGA DEL EXPEDIENTE A REVISORES URBANOS | F19: 1 | H19: 1 | J19: 0 | K19: OK
A20: LNM7 - 0525 - Surco - Arq. Edinson Rufasto | B20: Exp. Licencia mod. B | C20: ESTRUCTURAS | D20: ESTRUCTURAS - Detalle y corte de cisterna | E20: V 3.0 - PRELIMINAR A ENTREGA DEL EXPEDIENTE A REVISORES URBANOS | F20: 2 | H20: 2 | I20: -1 | J20: 0 | K20: OK
A21: LNM7 - 0525 - Surco - Arq. Edinson Rufasto | B21: Exp. Licencia mod. B | C21: ESTRUCTURAS | D21: ESTRUCTURAS - Especificaciones generales | E21: V 3.0 - PRELIMINAR A ENTREGA DEL EXPEDIENTE A REVISORES URBANOS | F21: 1 | H21: 1 | J21: 0 | K21: OK
A22: LNM7 - 0525 - Surco - Arq. Edinson Rufasto | B22: Exp. Licencia mod. B | C22: ESTRUCTURAS | D22: ESTRUCTURAS - Memoria de cálculo estructural | E22: V 3.0 - PRELIMINAR A ENTREGA DEL EXPEDIENTE A REVISORES URBANOS | F22: 2 | H22: 2 | I22: -1 | J22: 0 | K22: OK
A23: LNM7 - 0525 - Surco - Arq. Edinson Rufasto | B23: Exp. Licencia mod. B | C23: ESTRUCTURAS | D23: ESTRUCTURAS - Compatibilizacion con especialidades | E23: V 3.0 - PRELIMINAR A ENTREGA DEL EXPEDIENTE A REVISORES URBANOS | F23: 2 | H23: 2 | I23: -2 | J23: 0 | K23: OK
A24: LNM7 - 0525 - Surco - Arq. Edinson Rufasto | B24: Exp. Licencia mod. B | C24: ESTRUCTURAS | D24: ESTRUCTURAS - Reunión con cliente | E24: V 3.0 - PRELIMINAR A ENTREGA DEL EXPEDIENTE A REVISORES URBANOS | F24: 0 | G24: 4 | H24: 4 | I24: -4 | J24: 0 | K24: OK
A25: LNM7 - 0525 - Surco - Arq. Edinson Rufasto | B25: Exp. Licencia mod. B | C25: ESTRUCTURAS | D25: ESTRUCTURAS - Revision de Revisores | E25: V 3.1 - ENTREGA TÉCNICA FINAL DE EXPEDIENTE A REVISORES URBANOS | F25: 0 | H25: 0 | J25: 0 | K25: OK
A26: LNM7 - 0525 - Surco - Arq. Edinson Rufasto | B26: Exp. Licencia mod. B | C26: ESTRUCTURAS | D26: ESTRUCTURAS - Lev. de Observaciones de revisores | E26: V 4.0 - PRELIMINAR A ENTREGA DEL EXPEDIENTE A MUNICIPALIDAD | F26: 9 | H26: 9 | J26: 9 | K26: OK
A27: LNM7 - 0525 - Surco - Arq. Edinson Rufasto | B27: Exp. Licencia mod. B | C27: ESTRUCTURAS | D27: ESTRUCTURAS - Revision de Municipalidad | E27: V 4.1 - ENTREGA DEL EXPEDIENTE A MUNICIPALIDAD | F27: 0 | H27: 0 | J27: 0 | K27: OK
A28: LNM7 - 0525 - Surco - Arq. Edinson Rufasto | B28: Exp. Licencia mod. B | C28: ESTRUCTURAS | D28: ESTRUCTURAS - Lev. de Observaciones de Muni | E28: V 4.1 - ENTREGA DEL EXPEDIENTE A MUNICIPALIDAD | F28: 9 | H28: 9 | J28: 9 | K28: OK
A29: LNM7 - 0525 - Surco - Arq. Edinson Rufasto | B29: Exp. Licencia mod. B | C29: INST. ELECTRICAS | D29: IIEE - Mod. planos, según requerimiento de cliente | E29: V 3.0 - PRELIMINAR A ENTREGA DEL EXPEDIENTE A REVISORES URBANOS | F29: 4 | H29: 4 | I29: 9 | J29: 0 | K29: OK
A30: LNM7 - 0525 - Surco - Arq. Edinson Rufasto | B30: Exp. Licencia mod. B | C30: INST. ELECTRICAS | D30: IIEE - Plano de comunicaciones | E30: V 3.0 - PRELIMINAR A ENTREGA DEL EXPEDIENTE A REVISORES URBANOS | F30: 2 | H30: 2 | I30: 5 | J30: 0 | K30: OK
A31: LNM7 - 0525 - Surco - Arq. Edinson Rufasto | B31: Exp. Licencia mod. B | C31: INST. ELECTRICAS | D31: IIEE - Reunión con cliente para exp. prop. de puntos | E31: V 3.0 - PRELIMINAR A ENTREGA DEL EXPEDIENTE A REVISORES URBANOS | F31: 0 | G31: 4 | H31: 4 | I31: -3 | J31: 0 | K31: OK
A32: LNM7 - 0525 - Surco - Arq. Edinson Rufasto | B32: Exp. Licencia mod. B | C32: INST. ELECTRICAS | D32: IIEE - Revisión de revisores | E32: V 3.1 - ENTREGA TÉCNICA FINAL DE EXPEDIENTE A REVISORES URBANOS | F32: 0 | H32: 0 | I32: 0 | J32: 0 | K32: OK
A33: LNM7 - 0525 - Surco - Arq. Edinson Rufasto | B33: Exp. Licencia mod. B | C33: INST. ELECTRICAS | D33: IIEE - Lev. de observaciones de revisores | E33: V 4.0 - PRELIMINAR A ENTREGA DEL EXPEDIENTE A MUNICIPALIDAD | F33: 4 | H33: 4 | J33: 4 | K33: OK
A34: LNM7 - 0525 - Surco - Arq. Edinson Rufasto | B34: Exp. Licencia mod. B | C34: INST. ELECTRICAS | D34: IIEE - Revisión por Muni | E34: V 4.1 - ENTREGA DEL EXPEDIENTE A MUNICIPALIDAD | F34: 0 | H34: 0 | I34: 0 | J34: 0 | K34: OK
A35: LNM7 - 0525 - Surco - Arq. Edinson Rufasto | B35: Exp. Licencia mod. B | C35: INST. ELECTRICAS | D35: IIEE - Lev. de observaciones de Municipalidad | E35: V 4.0 - PRELIMINAR A ENTREGA DEL EXPEDIENTE A MUNICIPALIDAD | F35: 4 | H35: 4 | J35: 4 | K35: OK
A36: LNM7 - 0525 - Surco - Arq. Edinson Rufasto | B36: Exp. Licencia mod. B | C36: INST. SANITARIAS | D36: IISS - PLANOS DE AGUA | E36: V 3.0 - PRELIMINAR A ENTREGA DEL EXPEDIENTE A REVISORES URBANOS | F36: 4 | H36: 4 | I36: 1 | J36: 0 | K36: OK
A37: LNM7 - 0525 - Surco - Arq. Edinson Rufasto | B37: Exp. Licencia mod. B | C37: INST. SANITARIAS | D37: IISS - PLANOS DE DESAGUE | E37: V 3.0 - PRELIMINAR A ENTREGA DEL EXPEDIENTE A REVISORES URBANOS | F37: 4 | H37: 4 | I37: -1 | J37: 0 | K37: OK
A38: LNM7 - 0525 - Surco - Arq. Edinson Rufasto | B38: Exp. Licencia mod. B | C38: INST. SANITARIAS | D38: IISS - Plano de detalle + Plantas actualizada | E38: V 3.0 - PRELIMINAR A ENTREGA DEL EXPEDIENTE A REVISORES URBANOS | F38: 0.5 | H38: 0.5 | I38: -0.5 | J38: 0 | K38: OK
A39: LNM7 - 0525 - Surco - Arq. Edinson Rufasto | B39: Exp. Licencia mod. B | C39: INST. SANITARIAS | D39: IISS - Isométrico de agua | E39: V 3.0 - PRELIMINAR A ENTREGA DEL EXPEDIENTE A REVISORES URBANOS | F39: 0.5 | H39: 0.5 | I39: -0.5 | J39: 0 | K39: OK
A40: LNM7 - 0525 - Surco - Arq. Edinson Rufasto | B40: Exp. Licencia mod. B | C40: INST. SANITARIAS | D40: IISS - Excel de cálculos sanitarios | E40: V 3.0 - PRELIMINAR A ENTREGA DEL EXPEDIENTE A REVISORES URBANOS | F40: 1 | H40: 1 | I40: -1 | J40: 0 | K40: OK
...

Sheet MH-ONX8 - 0825 - Breña - Dario
A1: NOMBRE DE PROYECTO | B1: TIPO DE EXPEDIENTE | C1: ESPECIALIDAD | D1: PARTIDA | E1: VERSIÓN | F1: HORAS CALENDARIO TECNICOS LABORADOS PARA PERSONA CON RENDIMIENTO AL 100% | G1: HORAS CALENDARIO EN REUNIONES CON CLIENTES PARA PERSONA CON RENDIMIENTO AL 100% | H1: TOTAL | I1: HORAS ADICIONALES | J1: TOTAL HORAS RESTANTES | K1: Column11
A2: ONX8 - 0825 - Breña - Dario | B2: Exp. Obra + EMS | C2: ARQUITECTURA | D2: ARQUITECTURA - Memoria arquitectura | E2: V 2.0 - PRELIMINAR A ENTREGA DEL EXPEDIENTE | F2: 2 | H2: 2 | J2: 2 | K2: OK
A3: ONX8 - 0825 - Breña - Dario | B3: Exp. Obra + EMS | C3: ARQUITECTURA | D3: ARQUITECTURA - Memoria de seguridad | E3: V 2.0 - PRELIMINAR A ENTREGA DEL EXPEDIENTE | F3: 1 | H3: 1 | J3: 1 | K3: OK
A4: ONX8 - 0825 - Breña - Dario | B4: Exp. Obra + EMS | C4: ARQUITECTURA | D4: ARQUITECTURA - Bloque para especialidades | E4: V 2.0 - PRELIMINAR A ENTREGA DEL EXPEDIENTE | F4: 2 | H4: 2 | J4: 2 | K4: OK
A5: ONX8 - 0825 - Breña - Dario | B5: Exp. Obra + EMS | C5: ARQUITECTURA | D5: ARQUITECTURA - Propuesta de render 3D | E5: V 2.0 - PRELIMINAR A ENTREGA DEL EXPEDIENTE | F5: 1.5 | H5: 1.5 | J5: 1.5 | K5: OK
A6: ONX8 - 0825 - Breña - Dario | B6: Exp. Obra + EMS | C6: ARQUITECTURA | D6: TAREAS ADMINISTRATIVAS - Reunión para arquitectura de interiores | E6: V 1.0 - PRELIMINAR A LA APROBACIÓN ARQUITECTÓNICA | F6: 0 | G6: 10 | H6: 9.9916667 | J6: 9.9916667 | K6: OK
A7: ONX8 - 0825 - Breña - Dario | B7: Exp. Obra + EMS | C7: ARQUITECTURA | D7: ARQUITECTURA - Memoria arquitectura | E7: V 2.0 - PRELIMINAR A ENTREGA DEL EXPEDIENTE | F7: 0 | G7: 1 | H7: 1 | J7: 1 | K7: OK
A8: ONX8 - 0825 - Breña - Dario | B8: Exp. Obra + EMS | C8: ARQUITECTURA | D8: TAREAS ADMINISTRATIVAS - Reunión para aprobación de fachadas en 3D | E8: V 2.0 - PRELIMINAR A ENTREGA DEL EXPEDIENTE | F8: 0 | H8: 0 | J8: 0 | K8: OK
A9: ONX8 - 0825 - Breña - Dario | B9: Exp. Obra + EMS | C9: ARQUITECTURA | D9: TAREAS ADMINISTRATIVAS - Reunión para aprobación de fachadas en 3D | E9: V 2.0 - PRELIMINAR A ENTREGA DEL EXPEDIENTE | F9: 0 | H9: 0 | J9: 0 | K9: OK
A10: ONX8 - 0825 - Breña - Dario | B10: Exp. Obra + EMS | C10: ARQUITECTURA | D10: TAREAS ADMINISTRATIVAS - Reunión para aprobación de fachadas en 3D | E10: V 2.0 - PRELIMINAR A ENTREGA DEL EXPEDIENTE | F10: 0 | H10: 0 | J10: 0 | K10: OK
A11: ONX8 - 0825 - Breña - Dario | B11: Exp. Obra + EMS | C11: ARQUITECTURA | D11: TAREAS ADMINISTRATIVAS - Reunión para aprobación de fachadas en 3D | E11: V 2.0 - PRELIMINAR A ENTREGA DEL EXPEDIENTE | F11: 0 | H11: 0 | J11: 0 | K11: OK
A12: ONX8 - 0825 - Breña - Dario | B12: Exp. Obra + EMS | C12: ARQUITECTURA | D12: TAREAS ADMINISTRATIVAS - Reunión para aprobación de fachadas en 3D | E12: V 2.0 - PRELIMINAR A ENTREGA DEL EXPEDIENTE | F12: 0 | H12: 0 | J12: 0 | K12: OK
A13: ONX8 - 0825 - Breña - Dario | B13: Exp. Obra + EMS | C13: ARQUITECTURA | D13: TAREAS ADMINISTRATIVAS - Reunión para aprobación de fachadas en 3D | E13: V 2.0 - PRELIMINAR A ENTREGA DEL EXPEDIENTE | F13: 0 | H13: 0 | J13: 0 | K13: OK
A14: ONX8 - 0825 - Breña - Dario | B14: Exp. Obra + EMS | C14: ARQUITECTURA | D14: TAREAS ADMINISTRATIVAS - Reunión para aprobación de fachadas en 3D | E14: V 2.0 - PRELIMINAR A ENTREGA DEL EXPEDIENTE | F14: 0 | H14: 0 | J14: 0 | K14: OK
A15: ONX8 - 0825 - Breña - Dario | B15: Exp. Obra + EMS | C15: ARQUITECTURA | D15: TAREAS ADMINISTRATIVAS - Reunión para aprobación de fachadas en 3D | E15: V 2.0 - PRELIMINAR A ENTREGA DEL EXPEDIENTE | F15: 4 | H15: 4 | J15: 4 | K15: OK
A16: ONX8 - 0825 - Breña - Dario | B16: Exp. Obra + EMS | C16: ARQUITECTURA | D16: TAREAS ADMINISTRATIVAS - Reunión para aprobación de fachadas en 3D | E16: V 2.1 - ENTREGA TÉCNICA FINAL DE EXPEDIENTE | F16: 0 | H16: 0 | J16: 0 | K16: OK
A17: ONX8 - 0825 - Breña - Dario | B17: Exp. Obra + EMS | C17: ARQUITECTURA | D17: TAREAS ADMINISTRATIVAS - Reunión para aprobación de fachadas en 3D | E17: V 2.0 - PRELIMINAR A ENTREGA DEL EXPEDIENTE | F17: 1 | H17: 1 | J17: 1 | K17: OK
A18: ONX8 - 0825 - Breña - Dario | B18: Exp. Obra + EMS | C18: ARQUITECTURA | D18: TAREAS ADMINISTRATIVAS - Reunión para aprobación de fachadas en 3D | E18: V 2.0 - PRELIMINAR A ENTREGA DEL EXPEDIENTE | F18: 0.5 | H18: 0.5 | J18: 0.5 | K18: OK
C19: ARQUITECTURA | D19: TAREAS ADMINISTRATIVAS - Reunión para aprobación de fachadas en 3D

Sheet MH-ONM3-1125-Jicamarca-Giovann
A1: NOMBRE DE PROYECTO | B1: TIPO DE EXPEDIENTE | C1: ESPECIALIDAD | D1: PARTIDA | E1: VERSIÓN | F1: HORAS CALENDARIO TECNICOS LABORADOS PARA PERSONA CON RENDIMIENTO AL 100% | G1: HORAS CALENDARIO EN REUNIONES CON CLIENTES PARA PERSONA CON RENDIMIENTO AL 100% | H1: TOTAL | I1: HORAS ADICIONALES | J1: TOTAL HORAS RESTANTES | K1: Column11
A2: ONM3 - 1125 - Jicamarca - Giovanna Maldonado | B2: Exp. Obra + EMS | C2: ARQUITECTURA | D2: TAREAS ADMINISTRATIVAS - Corroborar bloque actualizado en todas las especialidades | E2: V 2.0 - PRELIMINAR A ENTREGA DEL EXPEDIENTE | F2: 0 | H2: 0 | J2: 0 | K2: OK
A3: ONM3 - 1125 - Jicamarca - Giovanna Maldonado | B3: Exp. Obra + EMS | C3: ESTRUCTURAS | D3: ESTRUCTURAS - Planos de diseño de aceros de encofrados | E3: V 2.0 - PRELIMINAR A ENTREGA DEL EXPEDIENTE | F3: 2 | H3: 2 | I3: -2 | J3: 0 | K3: OK
A4: ONM3 - 1125 - Jicamarca - Giovanna Maldonado | B4: Exp. Obra + EMS | C4: ESTRUCTURAS | D4: ESTRUCTURAS - Planos de encofrados de techos | E4: V 2.0 - PRELIMINAR A ENTREGA DEL EXPEDIENTE | F4: 3.5 | H4: 3.5 | I4: -3.5 | J4: 0 | K4: OK
A5: ONM3 - 1125 - Jicamarca - Giovanna Maldonado | B5: Exp. Obra + EMS | C5: ESTRUCTURAS | D5: ESTRUCTURAS - Detalle de placas | E5: V 2.0 - PRELIMINAR A ENTREGA DEL EXPEDIENTE | F5: 19.986667 | H5: 19.986667 | I5: -19.98 | J5: 0.0066666667 | K5: OK
A6: ONM3 - 1125 - Jicamarca - Giovanna Maldonado | B6: Exp. Obra + EMS | C6: ESTRUCTURAS | D6: ESTRUCTURAS - Cuadro de columnas | E6: V 2.0 - PRELIMINAR A ENTREGA DEL EXPEDIENTE | F6: 2 | H6: 2 | I6: -2 | J6: 0 | K6: OK
A7: ONM3 - 1125 - Jicamarca - Giovanna Maldonado | B7: Exp. Obra + EMS | C7: ESTRUCTURAS | D7: ESTRUCTURAS - Cuadro de vigas en encofrados | E7: V 2.0 - PRELIMINAR A ENTREGA DEL EXPEDIENTE | F7: 1 | H7: 1 | I7: -1 | J7: 0 | K7: OK
A8: ONM3 - 1125 - Jicamarca - Giovanna Maldonado | B8: Exp. Obra + EMS | C8: ESTRUCTURAS | D8: ESTRUCTURAS - Desarrollo de vigas | E8: V 2.0 - PRELIMINAR A ENTREGA DEL EXPEDIENTE | F8: 2 | H8: 2 | I8: -2 | J8: 0 | K8: OK
A9: ONM3 - 1125 - Jicamarca - Giovanna Maldonado | B9: Exp. Obra + EMS | C9: ESTRUCTURAS | D9: ESTRUCTURAS - Detalle y corte de cisterna | E9: V 2.0 - PRELIMINAR A ENTREGA DEL EXPEDIENTE | F9: 2 | H9: 2 | I9: -2 | J9: 0 | K9: OK
A10: ONM3 - 1125 - Jicamarca - Giovanna Maldonado | B10: Exp. Obra + EMS | C10: ESTRUCTURAS | D10: ESTRUCTURAS - Cortes de cimentación | E10: V 2.0 - PRELIMINAR A ENTREGA DEL EXPEDIENTE | F10: 1 | H10: 1 | I10: -1 | J10: 0 | K10: OK
A11: ONM3 - 1125 - Jicamarca - Giovanna Maldonado | B11: Exp. Obra + EMS | C11: ESTRUCTURAS | D11: ESTRUCTURAS - Especificaciones generales | E11: V 2.0 - PRELIMINAR A ENTREGA DEL EXPEDIENTE | F11: 0.5 | H11: 0.5 | I11: -0.5 | J11: 0 | K11: OK
A12: ONM3 - 1125 - Jicamarca - Giovanna Maldonado | B12: Exp. Obra + EMS | C12: ESTRUCTURAS | D12: ESTRUCTURAS - Memoria de cálculo estructural | E12: V 2.0 - PRELIMINAR A ENTREGA DEL EXPEDIENTE | F12: 2 | H12: 2 | I12: -2 | J12: 0 | K12: OK
A13: ONM3 - 1125 - Jicamarca - Giovanna Maldonado | B13: Exp. Obra + EMS | C13: ESTRUCTURAS | D13: ESTRUCTURAS - Compatibilización con especialidades | E13: V 2.0 - PRELIMINAR A ENTREGA DEL EXPEDIENTE | F13: 3 | H13: 3 | I13: -3 | J13: 0 | K13: OK
A14: ONM3 - 1125 - Jicamarca - Giovanna Maldonado | B14: Exp. Obra + EMS | C14: INST. ELECTRICAS | D14: IIEE - Propuesta de puntos | E14: V 1.0 - PRELIMINAR A LA APROBACIÓN ARQUITECTÓNICA | F14: 3 | H14: 3 | I14: -3 | J14: 0 | K14: OK
... A20: ONM3 - 1125 - Jicamarca - Giovanna Maldonado | B20: Exp. Obra + EMS | C20: GESTIÓN Y ADMINISTRACIÓN | D20: TAREAS ADMINISTRATIVAS - COORDINAR ENTREGA DE EXPEDIENTE CON CLIENTE | E20: V 2.0 - PRELIMINAR A ENTREGA DEL EXPEDIENTE | F20: 0 | H20: 0 | I20: 0 | J20: 0 | K20: OK

Sheet MH-LNC2-Cieneguilla-Sanny & Bry
A1: NOMBRE DE PROYECTO | B1: TIPO DE EXPEDIENTE | C1: ESPECIALIDAD | D1: PARTIDA | E1: VERSIÓN | F1: HORAS CALENDARIO TECNICOS LABORADOS PARA PERSONA CON RENDIMIENTO AL 100% | G1: HORAS CALENDARIO EN REUNIONES CON CLIENTES PARA PERSONA CON RENDIMIENTO AL 100% | H1: TOTAL | I1: HORAS ADICIONALES | J1: TOTAL HORAS RESTANTES | K1: Column11
A2: LNC2-Cieneguilla-Sanny & Bryan | B2: Exp. Licencia mod. B | C2: ARQUITECTURA | D2: ARQUITECTURA - Revision de Revisores | E2: V 2.1 - ENTREGA TÉCNICA FINAL DE EXPEDIENTE A REVISORES | F2: 0 | H2: 0 | J2: 0 | K2: OK
A3: LNC2-Cieneguilla-Sanny & Bryan | B3: Exp. Licencia mod. B | C3: ARQUITECTURA | D3: ARQUITECTURA - Lev. de Observaciones de revisores | E3: V 2.0 - PRELIMINAR A ENTREGA A REVISORES | F3: 5 | H3: 5 | I3: -5 | J3: 0 | K3: OK
A4: LNC2-Cieneguilla-Sanny & Bryan | B4: Exp. Licencia mod. B | C4: ARQUITECTURA | D4: TAREAS ADMINISTRATIVAS - Corroborar bloque actualizado en todas las especialidades | E4: V 3.0 - PRELIMINAR A ENTREGA A MUNI | F4: 0 | H4: 0 | J4: 0 | K4: OK
A5: LNC2-Cieneguilla-Sanny & Bryan | B5: Exp. Licencia mod. B | C5: ARQUITECTURA | D5: TAREAS ADMINISTRATIVAS - MANDAR A IMPRENTA 3 JUEGOS DE EXPEDIENTE A PLOTEAR | E5: V 3.0 - PRELIMINAR A ENTREGA A MUNI | F5: 3.5 | H5: 3.5 | J5: 3.5 | K5: OK
A6: LNC2-Cieneguilla-Sanny & Bryan | B6: Exp. Licencia mod. B | C6: ARQUITECTURA | D6: TAREAS ADMINISTRATIVAS - FIRMAR EXPEDIENTE | E6: V 3.0 - PRELIMINAR A ENTREGA A MUNI | F6: 4 | H6: 4 | J6: 4 | K6: OK
A7: LNC2-Cieneguilla-Sanny & Bryan | B7: Exp. Licencia mod. B | C7: ARQUITECTURA | D7: TAREAS ADMINISTRATIVAS - ESCANEA DE EXPEDIENTE A REVISORES | E7: V 3.0 - PRELIMINAR A ENTREGA A MUNI | F7: 0 | H7: 0 | J7: 0 | K7: OK
A8: LNC2-Cieneguilla-Sanny & Bryan | B8: Exp. Licencia mod. B | C8: ARQUITECTURA | D8: ARQUITECTURA - Lev. de observaciones de municipalidad | E8: V 3.0 - PRELIMINAR A ENTREGA A MUNI | F8: 5 | H8: 5 | J8: 5 | K8: OK
A9: LNC2-Cieneguilla-Sanny & Bryan | B9: Exp. Licencia mod. B | C9: ARQUITECTURA | D9: ARQUITECTURA - Revisión de municipalidad | E9: V 3.1 - ENTREGA TÉCNICA FINAL DE EXPEDIENTE A MUNI | F9: 0 | H9: 0 | J9: 0 | K9: OK
A10: LNC2-Cieneguilla-Sanny & Bryan | B10: Exp. Licencia mod. B | C10: ESTRUCTURAS | D10: ESTRUCTURAS - Revision de Revisores | E10: V 2.1 - ENTREGA TÉCNICA FINAL DE EXPEDIENTE A REVISORES | F10: 0 | H10: 0 | J10: 0 | K10: OK
A11: LNC2-Cieneguilla-Sanny & Bryan | B11: Exp. Licencia mod. B | C11: ESTRUCTURAS | D11: ESTRUCTURAS - Memoria de sostenimiento | E11: V 2.0 - PRELIMINAR A ENTREGA A REVISORES | F11: 1 | H11: 1 | I11: -1 | J11: 0 | K11: OK
A12: LNC2-Cieneguilla-Sanny & Bryan | B12: Exp. Licencia mod. B | C12: ESTRUCTURAS | D12: ESTRUCTURAS - Lev. de Observaciones de revisores | E12: V 3.0 - PRELIMINAR A ENTREGA A MUNI | F12: 9 | H12: 9 | J12: 9 | K12: OK
A13: LNC2-Cieneguilla-Sanny & Bryan | B13: Exp. Licencia mod. B | C13: ESTRUCTURAS | D13: ESTRUCTURAS - Revision de Municipalidad | E13: V 3.1 - ENTREGA TÉCNICA FINAL DE EXPEDIENTE A MUNI | F13: 0 | H13: 0 | J13: 0 | K13: OK
A14: LNC2-Cieneguilla-Sanny & Bryan | B14: Exp. Licencia mod. B | C14: ESTRUCTURAS | D14: ESTRUCTURAS - Lev. de Observaciones de Muni | E14: V 3.0 - PRELIMINAR A ENTREGA A MUNI | F14: 9 | H14: 9 | J14: 9 | K14: OK
A15: LNC2-Cieneguilla-Sanny & Bryan | B15: Exp. Licencia mod. B | C15: INST. ELECTRICAS | D15: IIEE - Revision de Revisores | E15: V 2.1 - ENTREGA TÉCNICA FINAL DE EXPEDIENTE A REVISORES | F15: 0 | H15: 0 | J15: 0 | K15: OK
A16: LNC2-Cieneguilla-Sanny & Bryan | B16: Exp. Licencia mod. B | C16: INST. ELECTRICAS | D16: IIEE - Lev. de Observaciones de revisores | E16: V 3.0 - PRELIMINAR A ENTREGA A MUNI | F16: 5 | H16: 5 | J16: 5 | K16: OK
A17: LNC2-Cieneguilla-Sanny & Bryan | B17: Exp. Licencia mod. B | C17: INST. ELECTRICAS | D17: IIEE - Lev. de Observaciones de Muni | E17: V 3.0 - PRELIMINAR A ENTREGA A MUNI | F17: 5 | H17: 5 | J17: 5 | K17: OK
A18: LNC2-Cieneguilla-Sanny & Bryan | B18: Exp. Licencia mod. B | C18: INST. ELECTRICAS | D18: IIEE - Revision de Municipalidad | E18: V 3.1 - ENTREGA TÉCNICA FINAL DE EXPEDIENTE A MUNI | F18: 0 | H18: 0 | J18: 0 | K18: OK
A19: LNC2-Cieneguilla-Sanny & Bryan | B19: Exp. Licencia mod. B | C19: INST. SANITARIAS | D19: IISS - Revision de Revisores | E19: V 2.1 - ENTREGA TÉCNICA FINAL DE EXPEDIENTE A REVISORES | F19: 0 | H19: 0 | J19: 0 | K19: OK
A20: LNC2-Cieneguilla-Sanny & Bryan | B20: Exp. Licencia mod. B | C20: INST. SANITARIAS | D20: IISS - Lev. de Observaciones de revisores | E20: V 3.0 - PRELIMINAR A ENTREGA A MUNI | F20: 5 | H20: 5 | J20: 5 | K20: OK
A21: LNC2-Cieneguilla-Sanny & Bryan | B21: Exp. Licencia mod. B | C21: INST. SANITARIAS | D21: IISS - Lev. de Observaciones de Muni | E21: V 3.0 - PRELIMINAR A ENTREGA A MUNI | F21: 5 | H21: 5 | J21: 5 | K21: OK
A22: LNC2-Cieneguilla-Sanny & Bryan | B22: Exp. Licencia mod. B | C22: INST. SANITARIAS | D22: IISS - Revision de Municipalidad | E22: V 3.1 - ENTREGA TÉCNICA FINAL DE EXPEDIENTE A MUNI | F22: 0 | H22: 0 | J22: 0 | K22: OK
A23: LNC2-Cieneguilla-Sanny & Bryan | B23: Exp. Licencia mod. B | C23: GESTIÓN Y ADMINISTRACIÓN | D23: TAREAS ADMINISTRATIVAS - ENTREGA DE EXPEDIENTE FINAL FIRMADO A MUNICIPALIDAD | E23: V 3.1 - ENTREGA TÉCNICA FINAL DE EXPEDIENTE A MUNI | F23: 0 | H23: 0 | J23: 0 | K23: OK
A24: LNC2-Cieneguilla-Sanny & Bryan | B24: Exp. Licencia mod. B | C24: GESTIÓN Y ADMINISTRACIÓN | D24: TAREAS ADMINISTRATIVAS - EMISIÓN DE LICENCIA DE EDIFICACIÓN | E24: V 3.1 - ENTREGA TÉCNICA FINAL DE EXPEDIENTE A MUNI | F24: 5 | H24: 5 | J24: 5 | K24: OK

Sheet MH-LNM5_0425-SAN MIGUEL-CAR
A1: NOMBRE DE PROYECTO | B1: TIPO DE EXPEDIENTE | C1: ESPECIALIDAD | D1: PARTIDA | E1: VERSIÓN | F1: HORAS CALENDARIO TECNICOS LABORADOS PARA PERSONA CON RENDIMIENTO AL 100% | G1: HORAS CALENDARIO EN REUNIONES CON CLIENTES PARA PERSONA CON RENDIMIENTO AL 100% | H1: TOTAL | I1: HORAS ADICIONALES | J1: TOTAL HORAS RESTANTES | K1: Column11
A2: LNM5_0425 - SAN MIGUEL - CARLOS Y ANA. | B2: Exp. Licencia mod. B | C2: ARQUITECTURA | D2: TAREAS ADMINISTRATIVAS - Reunión para aprobación de fachadas en 3D | E2: V 3.0 - PRELIMINAR A ENTREGA A MUNI | F2: 0 | G2: 3 | H2: 3 | J2: 3 | K2: OK
A3: LNM5_0425 - SAN MIGUEL - CARLOS Y ANA. | B3: Exp. Licencia mod. B | C3: ARQUITECTURA | D3: ARQUITECTURA - Render 3D | E3: V 3.0 - PRELIMINAR A ENTREGA A MUNI | F3: 30 | H3: 30 | J3: 30 | K3: OK
A4: LNM5_0425 - SAN MIGUEL - CARLOS Y ANA. | B4: Exp. Licencia mod. B | C4: ARQUITECTURA | D4: TAREAS ADMINISTRATIVAS - Corroborar membrete de todas las especialidades | E4: V 3.0 - PRELIMINAR A ENTREGA A MUNI | F4: 4 | H4: 4 | J4: 4 | K4: OK
A5: LNM5_0425 - SAN MIGUEL - CARLOS Y ANA. | B5: Exp. Licencia mod. B | C5: ARQUITECTURA | D5: TAREAS ADMINISTRATIVAS - MANDAR A IMPRENTA PLANOS A PLOTEAR | E5: V 3.0 - PRELIMINAR A ENTREGA A MUNI | F5: 3 | H5: 3 | J5: 3 | K5: OK
A6: LNM5_0425 - SAN MIGUEL - CARLOS Y ANA. | B6: Exp. Licencia mod. B | C6: ARQUITECTURA | D6: TAREAS ADMINISTRATIVAS - FIRMAR PLANOS | E6: V 3.0 - PRELIMINAR A ENTREGA A MUNI | F6: 3 | H6: 3 | J6: 3 | K6: OK
A7: LNM5_0425 - SAN MIGUEL - CARLOS Y ANA. | B7: Exp. Licencia mod. B | C7: ARQUITECTURA | D7: ARQUITECTURA - Lev. de observaciones del cliente | E7: V 3.0 - PRELIMINAR A ENTREGA A MUNI | F7: 3 | H7: 3 | J7: 3 | K7: OK
A8: LNM5_0425 - SAN MIGUEL - CARLOS Y ANA. | B8: Exp. Licencia mod. B | C8: ARQUITECTURA | D8: ARQUITECTURA - Lev. de observaciones de Muni | E8: V 3.0 - PRELIMINAR A ENTREGA A MUNI | F8: 4 | H8: 4 | J8: 4 | K8: OK
A9: LNM5_0425 - SAN MIGUEL - CARLOS Y ANA. | B9: Exp. Licencia mod. B | C9: ARQUITECTURA | D9: ARQUITECTURAS - Rev. de Municipalidad | E9: V 3.1 - ENTREGA TÉCNICA FINAL A MUNI | F9: 4 | H9: 4 | J9: 4 | K9: OK
A10: LNM5_0425 - SAN MIGUEL - CARLOS Y ANA. | B10: Exp. Licencia mod. B | C10: ESTRUCTURAS | D10: ESTRUCTURAS - Rev. de Revisores urbanos | E10: V 2.1 - ENTREGA TÉCNICA FINAL A REVISORES | F10: 0 | H10: 0 | J10: 0 | K10: OK
A11: LNM5_0425 - SAN MIGUEL - CARLOS Y ANA. | B11: Exp. Licencia mod. B | C11: ESTRUCTURAS | D11: ESTRUCTURAS - Lev. de revisores urbanos | E11: V 3.0 - PRELIMINAR A ENTREGA A MUNI | F11: 0 | H11: 0 | J11: 0 | K11: OK
A12: LNM5_0425 - SAN MIGUEL - CARLOS Y ANA. | B12: Exp. Licencia mod. B | C12: ESTRUCTURAS | D12: ESTRUCTURAS - Lev. de observaciones de Muni | E12: V 3.0 - PRELIMINAR A ENTREGA A MUNI | F12: 4 | H12: 4 | J12: 4 | K12: OK
A13: LNM5_0425 - SAN MIGUEL - CARLOS Y ANA. | B13: Exp. Licencia mod. B | C13: ESTRUCTURAS | D13: ESTRUCTURAS - Rev. de Municipalidad | E13: V 3.1 - ENTREGA TÉCNICA FINAL A MUNI | F13: 4 | H13: 4 | J13: 4 | K13: OK
A14: LNM5_0425 - SAN MIGUEL - CARLOS Y ANA. | B14: Exp. Licencia mod. B | C14: INST. SANITARIAS | D14: SANITARIAS - Lev. de revisores urbanos | E14: V 3.0 - PRELIMINAR A ENTREGA A MUNI | F14: 4 | H14: 4 | J14: 0 | K14: OK
... A23: LNM5_0425 - SAN MIGUEL - CARLOS Y ANA. | B23: Exp. Licencia mod. B | C23: INST. GAS | D23: IIGG - Rev. de Municipalidad | E23: V 3.1 - ENTREGA TÉCNICA FINAL A MUNI | F23: 0 | H23: 0 | J23: 0 | K23: OK
A24: LNM5_0425 - SAN MIGUEL - CARLOS Y ANA. | B24: Exp. Licencia mod. B | C24: GESTIÓN Y ADMINISTRACIÓN | D24: TAREAS ADMINISTRATIVAS - COORDINAR ENTREGA DE EXPEDIENTE CON CLIENTE | E24: V 3.0 - PRELIMINAR A ENTREGA A MUNI | F24: 0 | H24: 0

Sheet MH-LNX1 - 0325 - Breña - Juan C
A1: NOMBRE DE PROYECTO | B1: TIPO DE EXPEDIENTE | C1: ESPECIALIDAD | D1: PARTIDA | E1: VERSIÓN | F1: HORAS CALENDARIO TECNICOS LABORADOS PARA PERSONA CON RENDIMIENTO AL 100% | G1: HORAS CALENDARIO EN REUNIONES CON CLIENTES PARA PERSONA CON RENDIMIENTO AL 100% | H1: TOTAL | I1: HORAS ADICIONALES | J1: TOTAL HORAS RESTANTES | K1: Column11 | L1: Column12 | M1: Column13 | N1: Column14 | O1: Column15 | P1: Column16 | Q1: Column17 | R1: Column18 | S1: Column19 | T1: Column20 | U1: Column21 | V1: Column22 | W1: Column23 | X1: Column24 | Y1: Column25 | Z1: Column26 | AA1: Column27 | AB1: Column28 | AC1: Column29 | AD1: Column30 | AE1: Column31 | AF1: Column32 | AG1: Column33 | AH1: Column34 | AI1: Column35 | AJ1: Column36 | AK1: Column37 | AL1: Column38 | AM1: Column39 | AN1: Column40 | AO1: Column41 | AP1: Column42 | AQ1: Column43 | AR1: Column44 | AS1: Column45 | AT1: Column46 | AU1: Column47 | AV1: Column48 | AW1: Column49 | AX1: Column50 | AY1: Column51 | AZ1: Column52 | BA1: Column53 | BB1: Column54 | BC1: Column55 | BD1: Column56 | BE1: Column57 | BF1: Column58 | BG1: Column59
A2: LNX1 - 0325 - Breña - Juan Cano | B2: Exp. Licencia mod. B | C2: ESTRUCTURAS | D2: ESTRUCTURAS - Lev. de observaciones de Muni | E2: V 2.0 - PRELIMINAR A ENTREGA A LA MUNI | F2: 1 | H2: 1 | J2: 0 | K2: OK
A3: LNX1 - 0325 - Breña - Juan Cano | B3: Exp. Licencia mod. B | C3: ESTRUCTURAS | D3: ESTRUCTURAS - Revisión de municipalidad | E3: V 2.0 - PRELIMINAR A ENTREGA A LA MUNI | H3: 0 | J3: 0 | K3: OK
A4: LNX1 - 0325 - Breña - Juan Cano | B4: Exp. Licencia mod. B | C4: GESTIÓN Y ADMINISTRACIÓN | D4: TAREAS ADMINISTRATIVAS - COORDINAR ENTREGA DE EXPEDIENTE CON CLIENTE | E4: V 2.0 - PRELIMINAR A ENTREGA A LA MUNI | F4: 0 | H4: 0 | J4: 0 | K4: OK | N4: 0 | O4: 0 | R4: 0 | S4: 0 | V4: 0 | W4: 0 | Z4: 0 | AA4: 0 | AD4: 0 | AE4: 0 | AH4: 0 | AI4: 0 | AL4: 0 | AM4: 0 | AP4: 0 | AQ4: 0 | AT4: 0 | AU4: 0 | AX4: 0 | AY4: 0 | BB4: 0 | BC4: 0 | BF4: 0 | BG4: 0
A5: LNX1 - 0325 - Breña - Juan Cano | B5: Exp. Licencia mod. B | C5: GESTIÓN Y ADMINISTRACIÓN | D5: TAREAS ADMINISTRATIVAS - EMISION DE LA LICENCIA DE EDIFICACIÓN | E5: V 2.1 - ENTREGA TÉCNICA FINAL A MUNI | F5: 0 | H5: 0 | J5: 0 | K5: OK

Sheet MH-LNM7 - 0925 - Cedros - Ninah
A1: NOMBRE DE PROYECTO | B1: TIPO DE EXPEDIENTE | C1: ESPECIALIDAD | D1: PARTIDA | E1: VERSIÓN | F1: HORAS CALENDARIO TECNICOS LABORADOS PARA PERSONA CON RENDIMIENTO AL 100% | G1: HORAS CALENDARIO EN REUNIONES CON CLIENTES PARA PERSONA CON RENDIMIENTO AL 100% | H1: TOTAL | I1: HORAS ADICIONALES | J1: TOTAL HORAS RESTANTES | K1: Column11
A2: LNM7 - 0925 - Cedros de Villa Chorrillos - Arq. Martin Ninahuanca | B2: Exp. Licencia mod. B | C2: ARQUITECTURA | D2: ARQUITECTURA - Revision de Revisores | E2: V 2.1 - ENTREGA TÉCNICA FINAL DE EXPEDIENTE A REVISORES | F2: 0 | G2: 0 | H2: 0 | J2: 0 | K2: OK
A3: LNM7 - 0925 - Cedros de Villa Chorrillos - Arq. Martin Ninahuanca | B3: Exp. Licencia mod. B | C3: ARQUITECTURA | D3: ARQUITECTURA - Lev. de Observaciones de revisores | E3: V 3.0 - PRELIMINAR A ENTREGA A MUNI | F3: 5 | G3: 0 | H3: 5 | I3: -5 | J3: 0 | K3: OK
A4: LNM7 - 0925 - Cedros de Villa Chorrillos - Arq. Martin Ninahuanca | B4: Exp. Licencia mod. B | C4: ARQUITECTURA | D4: TAREAS ADMINISTRATIVAS - Corroborar bloque actualizado en todas las especialidades | E4: V 3.0 - PRELIMINAR A ENTREGA A MUNI | F4: 0 | G4: 0 | H4: 0 | J4: 0 | K4: OK
A5: LNM7 - 0925 - Cedros de Villa Chorrillos - Arq. Martin Ninahuanca | B5: Exp. Licencia mod. B | C5: ARQUITECTURA | D5: TAREAS ADMINISTRATIVAS - MANDAR A IMPRENTA 3 JUEGOS DE EXPEDIENTE A PLOTEAR | E5: V 3.0 - PRELIMINAR A ENTREGA A MUNI | F5: 3.5 | G5: 0 | H5: 3.5 | J5: 3.5 | K5: OK
A6: LNM7 - 0925 - Cedros de Villa Chorrillos - Arq. Martin Ninahuanca | B6: Exp. Licencia mod. B | C6: ARQUITECTURA | D6: TAREAS ADMINISTRATIVAS - FIRMAR EXPEDIENTE | E6: V 3.0 - PRELIMINAR A ENTREGA A MUNI | F6: 4 | G6: 0 | H6: 4 | J6: 4 | K6: OK
A7: LNM7 - 0925 - Cedros de Villa Chorrillos - Arq. Martin Ninahuanca | B7: Exp. Licencia mod. B | C7: ARQUITECTURA | D7: TAREAS ADMINISTRATIVAS - ESCANEA DE EXPEDIENTE A REVISORES | E7: V 3.0 - PRELIMINAR A ENTREGA A MUNI | F7: 0 | G7: 0 | H7: 0 | J7: 0 | K7: OK
A8: LNM7 - 0925 - Cedros de Villa Chorrillos - Arq. Martin Ninahuanca | B8: Exp. Licencia mod. B | C8: ARQUITECTURA | D8: ARQUITECTURA - Lev. de observaciones de municipalidad | E8: V 3.0 - PRELIMINAR A ENTREGA A MUNI | F8: 5 | G8: 0 | H8: 5 | J8: 5 | K8: OK
A9: LNM7 - 0925 - Cedros de Villa Chorrillos - Arq. Martin Ninahuanca | B9: Exp. Licencia mod. B | C9: ARQUITECTURA | D9: ARQUITECTURA - Revisión de municipalidad | E9: V 3.1 - ENTREGA TÉCNICA FINAL DE EXPEDIENTE A MUNI | F9: 0 | G9: 0 | H9: 0 | J9: 0 | K9: OK
A10: LNM7 - 0925 - Cedros de Villa Chorrillos - Arq. Martin Ninahuanca | B10: Exp. Licencia mod. B | C10: ESTRUCTURAS | D10: ESTRUCTURAS - Revision de Revisores | E10: V 2.1 - ENTREGA TÉCNICA FINAL DE EXPEDIENTE A REVISORES | F10: 0 | G10: 0 | H10: 0 | J10: 0 | K10: OK
A11: LNM7 - 0925 - Cedros de Villa Chorrillos - Arq. Martin Ninahuanca | B11: Exp. Licencia mod. B | C11: ESTRUCTURAS | D11: ESTRUCTURAS - Lev. de Observaciones de revisores | E11: V 3.0 - PRELIMINAR A ENTREGA A MUNI | F11: 9 | G11: 0 | H11: 9 | I11: -9 | J11: 0 | K11: OK
A12: LNM7 - 0925 - Cedros de Villa Chorrillos - Arq. Martin Ninahuanca | B12: Exp. Licencia mod. B | C12: ESTRUCTURAS | D12: ESTRUCTURAS - Revision de Municipalidad | E12: V 3.1 - ENTREGA TÉCNICA FINAL DE EXPEDIENTE A MUNI | F12: 0 | G12: 0 | H12: 0 | J12: 0 | K12: OK
A13: LNM7 - 0925 - Cedros de Villa Chorrillos - Arq. Martin Ninahuanca | B13: Exp. Licencia mod. B | C13: ESTRUCTURAS | D13: ESTRUCTURAS - Lev. de Observaciones de Muni | E13: V 3.0 - PRELIMINAR A ENTREGA A MUNI | F13: 9 | G13: 0 | H13: 9 | J13: 9 | K13: OK
A14: LNM7 - 0925 - Cedros de Villa Chorrillos - Arq. Martin Ninahuanca | B14: Exp. Licencia mod. B | C14: INST. ELECTRICAS | D14: IIEE - Revision de Revisores | E14: V 2.1 - ENTREGA TÉCNICA FINAL DE EXPEDIENTE A REVISORES | F14: 0 | G14: 0 | H14: 0 | J14: 0 | K14: OK
A15: LNM7 - 0925 - Cedros de Villa Chorrillos - Arq. Martin Ninahuanca | B15: Exp. Licencia mod. B | C15: INST. ELECTRICAS | D15: IIEE - Lev. de Observaciones de revisores | E15: V 3.0 - PRELIMINAR A ENTREGA A MUNI | F15: 5 | G15: 0 | H15: 5 | I15: -5 | J15: 0 | K15: OK
A16: LNM7 - 0925 - Cedros de Villa Chorrillos - Arq. Martin Ninahuanca | B16: Exp. Licencia mod. B | C16: INST. ELECTRICAS | D16: IIEE - Lev. de Observaciones de Muni | E16: V 3.0 - PRELIMINAR A ENTREGA A MUNI | F16: 5 | G16: 0 | H16: 5 | J16: 5 | K16: OK
A17: LNM7 - 0925 - Cedros de Villa Chorrillos - Arq. Martin Ninahuanca | B17: Exp. Licencia mod. B | C17: INST. ELECTRICAS | D17: IIEE - Revision de Municipalidad | E17: V 3.1 - ENTREGA TÉCNICA FINAL DE EXPEDIENTE A MUNI | F17: 0 | G17: 0 | H17: 0 | J17: 0 | K17: OK
A18: LNM7 - 0925 - Cedros de Villa Chorrillos - Arq. Martin Ninahuanca | B18: Exp. Licencia mod. B | C18: INST. SANITARIAS | D18: IISS - Revision de Revisores | E18: V 2.1 - ENTREGA TÉCNICA FINAL DE EXPEDIENTE A REVISORES | F18: 0 | G18: 0 | H18: 0 | J18: 0 | K18: OK
A19: LNM7 - 0925 - Cedros de Villa Chorrillos - Arq. Martin Ninahuanca | B19: Exp. Licencia mod. B | C19: INST. SANITARIAS | D19: IISS - Lev. de Observaciones de revisores | E19: V 3.0 - PRELIMINAR A ENTREGA A MUNI | F19: 4 | G19: 0 | H19: 4 | I19: -4 | J19: 0 | K19: OK
A20: LNM7 - 0925 - Cedros de Villa Chorrillos - Arq. Martin Ninahuanca | B20: Exp. Licencia mod. B | C20: INST. SANITARIAS | D20: IISS - Lev. de Observaciones de Muni | E20: V 3.0 - PRELIMINAR A ENTREGA A MUNI | F20: 4 | G20: 0 | H20: 4 | J20: 4 | K20: OK
A21: LNM7 - 0925 - Cedros de Villa Chorrillos - Arq. Martin Ninahuanca | B21: Exp. Licencia mod. B | C21: INST. SANITARIAS | D21: IISS - Revision de Municipalidad | E21: V 3.1 - ENTREGA TÉCNICA FINAL DE EXPEDIENTE A MUNI | F21: 0 | G21: 0 | H21: 0 | J21: 0 | K21: OK
A22: LNM7 - 0925 - Cedros de Villa Chorrillos - Arq. Martin Ninahuanca | B22: Exp. Licencia mod. B | C22: INST. GAS | D22: GAS - Revision de Revisores | E22: V 2.1 - ENTREGA TÉCNICA FINAL DE EXPEDIENTE A REVISORES | F22: 0 | G22: 0 | H22: 0 | J22: 0 | K22: OK
A23: LNM7 - 0925 - Cedros de Villa Chorrillos - Arq. Martin Ninahuanca | B23: Exp. Licencia mod. B | C23: INST. GAS | D23: GAS - Revisión de municipalidad | E23: V 3.1 - ENTREGA TÉCNICA FINAL DE EXPEDIENTE A MUNI | F23: 0 | G23: 0 | H23: 0 | J23: 0 | K23: OK
A24: LNM7 - 0925 - Cedros de Villa Chorrillos - Arq. Martin Ninahuanca | B24: Exp. Licencia mod. B | C24: GESTIÓN Y ADMINISTRACIÓN | D24: TAREAS ADMINISTRATIVAS - ENTREGA DE EXPEDIENTE FINAL FIRMADO A MUNICIPALIDAD | E24: V 3.1 - ENTREGA TÉCNICA FINAL DE EXPEDIENTE A MUNI | F24: 0 | G24: 0 | H24: 0 | J24: 0 | K24: OK
A25: LNM7 - 0925 - Cedros de Villa Chorrillos - Arq. Martin Ninahuanca | B25: Exp. Licencia mod. B | C25: GESTIÓN Y ADMINISTRACIÓN | D25: TAREAS ADMINISTRATIVAS - EMISIÓN DE LICENCIA DE EDIFICACIÓN | E25: V 3.1 - ENTREGA TÉCNICA FINAL DE EXPEDIENTE A MUNI | F25: 0 | G25: 0 | H25: 0 | J25: 0 | K25: OK

Sheet MH-ONC2_0725-SAN ANTONIO-PEDRO
A1: NOMBRE DE PROYECTO | B1: TIPO DE EXPEDIENTE | C1: ESPECIALIDAD | D1: PARTIDA | E1: VERSIÓN | F1: HORAS CALENDARIO TECNICOS LABORADOS PARA PERSONA CON RENDIMIENTO AL 100% | G1: HORAS CALENDARIO EN REUNIONES CON CLIENTES PARA PERSONA CON RENDIMIENTO AL 100% | H1: TOTAL | I1: HORAS ADICIONALES | J1: TOTAL HORAS RESTANTES | K1: Column11
A2: LNC2_0725 - SAN ANTONIO - PEDRO | B2: Exp. Licencia mod. B | C2: ARQUITECTURA | D2: GESTION DIRECTA - MANDAR A PLOTEAR A IMPRENTA 3 JUEGO DE EXPEDIENTE PARA CONDOMINIO | E2: V 2.0 - PRELIMINAR A ENTREGA DEL EXPEDIENTE A CONDOMINIO | F2: 2 | H2: 2 | J2: 2 | K2: OK
A3: LNC2_0725 - SAN ANTONIO - PEDRO | B3: Exp. Licencia mod. B | C3: ARQUITECTURA | D3: GESTION DIRECTA - FIRMA DE EXPEDIENTE DE CONDOMINIO | E3: V 2.0 - PRELIMINAR A ENTREGA DEL EXPEDIENTE A CONDOMINIO | F3: 3 | H3: 3 | J3: 3 | K3: OK
A4: LNC2_0725 - SAN ANTONIO - PEDRO | B4: Exp. Licencia mod. B | C4: ARQUITECTURA | D4: ARQUITECTURA - Presupuesto | E4: V 3.0 - PRELIMINAR A ENTREGA DEL EXPEDIENTE A MUNICIPALIDAD | F4: 1 | H4: 1 | J4: 1 | K4: OK
A5: LNC2_0725 - SAN ANTONIO - PEDRO | B5: Exp. Licencia mod. B | C5: ARQUITECTURA | D5: ARQUITECTURA - Llenar FUE (Formulario Único de Edificaciones) | E5: V 3.0 - PRELIMINAR A ENTREGA DEL EXPEDIENTE A MUNICIPALIDAD | F5: 1 | H5: 1 | J5: 1 | K5: OK
A6: LNC2_0725 - SAN ANTONIO - PEDRO | B6: Exp. Licencia mod. B | C6: ARQUITECTURA | D6: GESTION DIRECTA - MANDAR A PLOTEAR A IMPRENTA 3 JUEGO DE EXPEDIENTE PARA MUNI | E6: V 3.0 - PRELIMINAR A ENTREGA DEL EXPEDIENTE A MUNICIPALIDAD | F6: 2 | H6: 2 | J6: 2 | K6: OK
A7: LNC2_0725 - SAN ANTONIO - PEDRO | B7: Exp. Licencia mod. B | C7: ARQUITECTURA | D7: GESTION DIRECTA - FIRMA DE EXPEDIENTE MUNI | E7: V 3.0 - PRELIMINAR A ENTREGA DEL EXPEDIENTE A MUNICIPALIDAD | F7: 2 | H7: 2 | J7: 2 | K7: OK
A8: LNC2_0725 - SAN ANTONIO - PEDRO | B8: Exp. Licencia mod. B | C8: ARQUITECTURA | D8: ARQUITECTURA - Levantamiento de observaciones municipalidad | E8: V 3.0 - PRELIMINAR A ENTREGA DEL EXPEDIENTE A MUNICIPALIDAD | F8: 3 | H8: 3 | J8: 3 | K8: OK
A9: LNC2_0725 - SAN ANTONIO - PEDRO | B9: Exp. Licencia mod. B | C9: ARQUITECTURA | D9: ARQUITECTURA - Revisión de municipalidad | E9: V 3.1 - ENTREGA TÉCNICA FINAL DE EXPEDIENTE A MUNICIPALIDAD | F9: 0 | H9: 0 | J9: 0 | K9: OK
A10: LNC2_0725 - SAN ANTONIO - PEDRO | B10: Exp. Licencia mod. B | C10: ESTRUCTURAS | D10: ESTRUCTURAS - Lev. De observaciones | E10: V 3.0 - PRELIMINAR A ENTREGA DEL EXPEDIENTE A MUNICIPALIDAD | F10: 4 | H10: 4 | J10: 4 | K10: OK
A11: LNC2_0725 - SAN ANTONIO - PEDRO | B11: Exp. Licencia mod. B | C11: ESTRUCTURAS | D11: ESTRUCTURAS - Revisión de municipalidad | E11: V 3.1 - ENTREGA TÉCNICA FINAL DE EXPEDIENTE A MUNICIPALIDAD | F11: 0 | H11: 0 | J11: 0 | K11: OK
A12: LNC2_0725 - SAN ANTONIO - PEDRO | B12: Exp. Licencia mod. B | C12: INST. ELECTRICAS | D12: IIEE - Levantamiento de observaciones de Muni | E12: V 3.0 - PRELIMINAR A ENTREGA DEL EXPEDIENTE A MUNICIPALIDAD | F12: 5 | H12: 5 | J12: 5 | K12: OK
A13: LNC2_0725 - SAN ANTONIO - PEDRO | B13: Exp. Licencia mod. B | C13: INST. ELECTRICAS | D13: IIEE - Revisión de municipalidad | E13: V 3.1 - ENTREGA TÉCNICA FINAL DE EXPEDIENTE A MUNICIPALIDAD | F13: 0 | H13: 0 | J13: 0 | K13: OK
... A17: LNC2_0725 - SAN ANTONIO - PEDRO | B17: Exp. Licencia mod. B | C17: SUELOS | D17: EMS - Informe de EMS | E17: V 3.0 - PRELIMINAR A ENTREGA DEL EXPEDIENTE A MUNICIPALIDAD | F17: 2 | H17: 2 | J17: 2 | K17: OK

Sheet MH-LNM5 - San Miguel - Ing  Mar
A1: NOMBRE DE PROYECTO | B1: TIPO DE EXPEDIENTE | C1: ESPECIALIDAD | D1: PARTIDA | E1: VERSIÓN | F1: HORAS CALENDARIO TECNICOS LABORADOS PARA PERSONA CON RENDIMIENTO AL 100% | G1: HORAS CALENDARIO EN REUNIONES CON CLIENTES PARA PERSONA CON RENDIMIENTO AL 100% | H1: TOTAL | I1: HORAS ADICIONALES | J1: TOTAL HORAS RESTANTES | K1: Column11
A2: LNM5 - San Miguel - Ing. Mario Martín | B2: Exp. Licencia mod. B | C2: GESTIÓN Y ADMINISTRACIÓN | D2: INGRESAR EXPEDIENTE A MUNICIPALIDAD | E2: V 3.1 - ENTREGA TÉCNICA FINAL DE EXPEDIENTE A MUNICIPALIDAD | F2: 4 | H2: 4 | J2: 0 | K2: OK
A3: LNM5 - San Miguel - Ing. Mario Martín | B3: Exp. Licencia mod. B | C3: GESTIÓN Y ADMINISTRACIÓN | D3: TRAMITES ADMINISTRATIVOS - REVISIÓN DE EXP. POR MUNICIPALIDAD | E3: V 3.1 - ENTREGA TÉCNICA FINAL DE EXPEDIENTE A MUNICIPALIDAD | F3: 0 | H3: 0 | J3: 0 | K3: OK

Sheet MH-ORX5-1125-Surquillo-LuzSuare
A1: NOMBRE DE PROYECTO | B1: TIPO DE EXPEDIENTE | C1: ESPECIALIDAD | D1: PARTIDA | E1: VERSIÓN | F1: HORAS CALENDARIO TECNICOS LABORADOS PARA PERSONA CON RENDIMIENTO AL 100% | G1: HORAS CALENDARIO EN REUNIONES CON CLIENTES PARA PERSONA CON RENDIMIENTO AL 100% | H1: TOTAL | I1: HORAS ADICIONALES | J1: TOTAL HORAS RESTANTES | K1: Column11
A2: ORX5 - 1125 - Surquillo - Luz suarez | B2: Exp. Obra (COMERCIO) | C2: ARQUITECTURA | D2: ARQUITECTURA - Modificar arquitectura | E2: V 2.0 - PRELIMINAR A ENTREGA DEL EXPEDIENTE | F2: 5 | H2: 5 | J2: 5 | K2: OK
A3: ORX5 - 1125 - Surquillo - Luz suarez | B3: Exp. Obra (COMERCIO) | C3: ARQUITECTURA | D3: TAREAS ADMINISTRATIVAS - MANDAR A IMPRENTA PLANOS A PLOTEAR | E3: V 2.0 - PRELIMINAR A ENTREGA DEL EXPEDIENTE | F3: 0 | H3: 0 | J3: 0 | K3: OK
A4: ORX5 - 1125 - Surquillo - Luz suarez | B4: Exp. Obra (COMERCIO) | C4: ARQUITECTURA | D4: ARQUITECTURA - Memoria de seguridad | E4: V 2.0 - PRELIMINAR A ENTREGA DEL EXPEDIENTE | F4: 1 | H4: 1 | J4: 1 | K4: OK
A5: ORX5 - 1125 - Surquillo - Luz suarez | B5: Exp. Obra (COMERCIO) | C5: ARQUITECTURA | D5: ARQUITECTURA - Planos de señalización | E5: V 2.0 - PRELIMINAR A ENTREGA DEL EXPEDIENTE | F5: 2 | H5: 2 | J5: 2 | K5: OK
A6: ORX5 - 1125 - Surquillo - Luz suarez | B6: Exp. Obra (COMERCIO) | C6: ARQUITECTURA | D6: ARQUITECTURA - Planos de evacuación | E6: V 2.0 - PRELIMINAR A ENTREGA DEL EXPEDIENTE | F6: 4 | J6: 0 | K6: OK
A7: ORX5 - 1125 - Surquillo - Luz suarez | B7: Exp. Obra (COMERCIO) | C7: ARQUITECTURA | D7: ARQUITECTURA - Memoria de Arquitectura | E7: V 2.0 - PRELIMINAR A ENTREGA DEL EXPEDIENTE | F7: 1 | J7: 0 | K7: OK
A8: ORX5 - 1125 - Surquillo - Luz suarez | B8: Exp. Obra (COMERCIO) | C8: ARQUITECTURA | D8: ARQUITECTURA - Planos de corte y elevación | E8: V 2.0 - PRELIMINAR A ENTREGA DEL EXPEDIENTE | F8: 0 | J8: 0 | K8: OK
A9: ORX5 - 1125 - Surquillo - Luz suarez | B9: Exp. Obra (COMERCIO) | C9: ARQUITECTURA | D9: ARQUITECTURA - Propuesta de render 3D | E9: V 2.0 - PRELIMINAR A ENTREGA DEL EXPEDIENTE | F9: 6 | J9: 0 | K9: OK
