Workbook

Sheet Plan Maestro
A1: CRONOGRAMA DE OBRA
A2: OBRAS PRELIMINARES Y MOVIMIENTO DE TIERRAS | B2: SEM 01 | C2: SEM 02 | D2: SEM 03 | E2: SEM 04 | F2: SEM 05 | G2: SEM 06 | H2: SEM 07 | I2: SEM 08 | J2: SEM 09 | K2: SEM 10 | L2: SEM 11 | M2: SEM 12 | N2: SEM 13 | O2: SEM 14 | P2: SEM 15 | Q2: SEM 16
A3: OBRAS PRELIMINARES
A4: DEMOLICIÓN PARCIAL
A5: MOVIMIENTO DE TIERRAS
A6: SEGURIDAD Y SALUD
A7: 1 ER PISO
A8: OBRAS DE CONCRETO SIMPLE
A9: OBRAS DE CONCRETO ARMADO
A10: TABIQUERIA
A11: OBRAS HUMEDAS
A12: INSTALACIONES ELECTRICAS
A13: INSTALACIONES SANITARIAS
A14: 2 DO PISO
... A25: INSTALACIONES SANITARIAS

Sheet Look A Head
A1: LOOKAHEAD PLANNING - OBRA SURQUILLO
A3: ITEM | B3: DESCRIPCIÓN DE PARTIDAS | E3: Semana 01 (01/06 al 06/05) | L3: Semana 02 (08/06 al 13/06) | S3: Semana 03 (15/06 al 20/06)
E4: L | F4: M | G4: X | H4: J | I4: V | J4: S | K4: D | L4: L | M4: M | N4: X | O4: J | P4: V | Q4: S | R4: D | S4: L | T4: M | U4: X | V4: J | W4: V | X4: S | Y4: D
A5: 01.00.00.00 | B5: OBRAS PROVISIONALES, TRABAJOS PRELIMINARES, SEGURIDAD Y SALUD
A6: 01.01.00.00 | B6: OBRAS PROVISIONALES
A7: 01.01.01.00 | B7: TRANSPORTE DE EQUIPOS Y HERRAMIENTAS | C7: glb | D7: 1 | H7: X | I7: X
A8: 01.01.03.00 | B8: PROTECCIÓN CON MALLA RASCHELL | C8: ml | D8: 180 | H8: X | I8: X
A9: 01.02.00.00 | B9: DEMOLICIÓN Y MOVIMIENTO DE TIERRAS
A10: 01.02.01.00 | B10: DESMONTAJE Y ACARREO DE MATERIAL | C10: glb | D10: 1 | E10: X | F10: X | G10: X
A11: 01.02.02.00 | B11: APUNTALAMIENTO ESTRUCTURAL | C11: GLB | D11: 1 | H11: X | I11: X
A12: 01.02.03.00 | B12: DEMOLICIÓN DE MUROS DE AZOTEA | C12: glb | D12: 1 | J12: X
A13: 01.02.03.00 | B13: DEMOLICIÓN DE MUROS Y PISO DE 3ER PISO | C13: glb | D13: 1 | L13: X | M13: X
A14: 01.02.03.00 | B14: DEMOLICIÓN DE MUROS Y PISO DE 2DO PISO | C14: glb | D14: 1 | N14: X | O14: X
A15: 01.02.03.00 | B15: DEMOLICIÓN DE MUROS Y PISO DE 1ER PISO | C15: glb | D15: 1 | P15: X | Q15: X
B16: DEMOLICIÓN DE ZANJA PARA ZAPATAS | C16: glb | D16: 1 | S16: X | T16: X | U16: X
A17: 01.02.04.00 | B17: ELIMINACIÓN DE ESCOMBROS, DESMONTE | C17: glb | D17: 1 | Q17: X | X17: X
A18: 01.02.05.00 | B18: TRAZADO Y REPLANTEO S/EQUIPO | C18: m2 | D18: 206 | S18: X
B19: EXCAVACIÓN MANUAL DE ZANJA EN ZAPATAS | C19: m3 | T19: X
B20: COMPACTACIÓN PARA ZAPATAS | C20: m2 | U20: X
A21: 01.02.00.00 | B21: OBRAS DE CONCRETO ARMADO
B22: SOLADO DE CONCRETO | C22: m2 | V22: X
B23: ACERO DE ZAPATAS | C23: kg | W23: X
B24: ACERO DE PLACAS | C24: kg | X24: X
B25: VACIADO DE ZAPATAS | C25: m3 | X25: X
B26: ENCOFRADO DE PLACAS | C26: m2

Sheet Restricciones
A2: ANÁLISIS DE RESTRICCIONES
A4: ACTIVIDAD RELACIONADA | B4: MONTO ESTIMADO | C4: Fecha Max. | D4: TIPO DE RESTRICCIÓN | G4: RESPONSABLE | H4: ESTATUS
B5: MONTO ESTIMADO | D5: FINANZAS | E5: O.F. TECNICA | F5: M.OBRA
A6: Expediente de Anexo H | B6: 250 | C6: 46175 | E6: X | G6: Ing.Willy / Ing. Guillermo
A7: Cartel de Obra | B7: 200 | C7: 46177 | D7: X | G7: Francesa Barbieri
A8: Compras de palos y malla raschell | B8: 2000 | C8: 46178 | D8: X | E8: X | F8: X | G8: Ing. Guillermo / Barbieri
A9: EPPs, completos, polos y chalecos | B9: 2000 | C9: 46178 | D9: X | G9: Francesa Barbieri
A10: Planos de demolición | C10: 46176 | E10: X | G10: Arq. Pierina / Arq. Alan
A11: Actualizacion de planos de Estructuras | C11: 46183 | E11: X | G11: Ing. Willy / Ing. Cristhian
A12: Actualizacion de planos de Arquitectura | C12: 46183 | E12: X | G12: Arq. Pierina / Arq. Alan
B14: ============
A15: MONTO ESTIMADO DE INVERSIÓN | B15: =SUM(B6:B13) -> 4450
B19: planner
B20: jefe de produccion
B21: residente de obra

Sheet PPC S1
A1: PPC - OBRA SURQUILLO - SEMANA 1
A3: ITEM | B3: DESCRIPCIÓN DE PARTIDAS | C3: METRADO | D3: UNIDAD | E3: METRADO PLANIFICADO | F3: Semana 01 (01/06 al 06/05) | M3: METRADO REALIZADO | N3: % CUMPLIMIENTO | O3: CUMPLIMIENTO | P3: ANALISIS DE CAUSAS DE INCUMPLIMIENTO & MEDIDAS CORRECTIVAS
F4: L | G4: M | H4: X | I4: J | J4: V | K4: S | L4: D
A5: 01.00.00.00 | B5: OBRAS PROVISIONALES, TRABAJOS PRELIMINARES, SEGURIDAD Y SALUD | O5: SI/NO | P5: TIPO | Q5: COMENTARIO | R5: MEDIDA CORRECTIVVA
A6: 01.01.00.00 | B6: OBRAS PROVISIONALES
A7: 01.01.01.00 | B7: TRANSPORTE DE EQUIPOS Y HERRAMIENTAS | C7: glb | D7: 1 | E7: 1 | I7: X | J7: X | N7: =IF(M7>0,M7/E7,0) -> 0 | O7: =IF(N7=1,"SI","NO") -> NO
A8: 01.01.03.00 | B8: PROTECCIÓN CON MALLA RASCHELL | C8: ml | D8: 180 | E8: 180 | I8: X | J8: X | N8: =IF(M8>0,M8/E8,0) -> 0 | O8: =IF(N8=1,"SI","NO") -> NO
A9: 01.02.00.00 | B9: DEMOLICIÓN Y MOVIMIENTO DE TIERRAS
A10: 01.02.01.00 | B10: DESMONTAJE Y ACARREO DE MATERIAL | C10: glb | D10: 1 | E10: 1 | F10: X | G10: X | H10: X | N10: =IF(M10>0,M10/E10,0) -> 0 | O10: =IF(N10=1,"SI","NO") -> NO
A11: 01.02.02.00 | B11: APUNTALAMIENTO ESTRUCTURAL | C11: GLB | D11: 1 | E11: 1 | I11: X | J11: X | N11: =IF(M11>0,M11/E11,0) -> 0 | O11: =IF(N11=1,"SI","NO") -> NO
A12: 01.02.03.00 | B12: DEMOLICIÓN DE MUROS DE AZOTEA | C12: glb | D12: 1 | E12: 1 | K12: X | N12: =IF(M12>0,M12/E12,0) -> 0 | O12: =IF(N12=1,"SI","NO") -> NO
A13: 01.02.03.00 | B13: DEMOLICIÓN DE MUROS Y PISO DE 3ER PISO | C13: glb | D13: 1 | E13: 1 | N13: =IF(M13>0,M13/E13,0) -> 0 | O13: =IF(N13=1,"SI","NO") -> NO
A14: 01.02.03.00 | B14: DEMOLICIÓN DE MUROS Y PISO DE 2DO PISO | C14: glb | D14: 1 | E14: 1 | N14: =IF(M14>0,M14/E14,0) -> 0 | O14: =IF(N14=1,"SI","NO") -> NO
A15: 01.02.03.00 | B15: DEMOLICIÓN DE MUROS Y PISO DE 1ER PISO | C15: glb | D15: 1 | E15: 1 | N15: =IF(M15>0,M15/E15,0) -> 0 | O15: =IF(N15=1,"SI","NO") -> NO
B16: DEMOLICIÓN DE ZANJA PARA ZAPATAS | C16: glb | D16: 1 | E16: 1 | N16: =IF(M16>0,M16/E16,0) -> 0 | O16: =IF(N16=1,"SI","NO") -> NO
A17: 01.02.04.00 | B17: ELIMINACIÓN DE ESCOMBROS, DESMONTE | C17: glb | D17: 1 | E17: 1 | N17: =IF(M17>0,M17/E17,0) -> 0 | O17: =IF(N17=1,"SI","NO") -> NO
A18: 01.02.05.00 | B18: TRAZADO Y REPLANTEO S/EQUIPO | C18: m2 | D18: 206 | E18: 206 | N18: =IF(M18>0,M18/E18,0) -> 0 | O18: =IF(N18=1,"SI","NO") -> NO
B19: EXCAVACIÓN MANUAL DE ZANJA EN ZAPATAS | C19: m3 | N19: =IF(M19>0,M19/E19,0) -> 0 | O19: =IF(N19=1,"SI","NO") -> NO
B20: COMPACTACIÓN PARA ZAPATAS | C20: m2 | N20: =IF(M20>0,M20/E20,0) -> 0 | O20: =IF(N20=1,"SI","NO") -> NO
A21: 01.02.00.00 | B21: OBRAS DE CONCRETO ARMADO
B22: SOLADO DE CONCRETO | C22: m2 | N22: =IF(M22>0,M22/E22,0) -> 0 | O22: =IF(N22=1,"SI","NO") -> NO
B23: ACERO DE ZAPATAS | C23: kg | N23: =IF(M23>0,M23/E23,0) -> 0 | O23: =IF(N23=1,"SI","NO") -> NO
B24: ACERO DE PLACAS | C24: kg | N24: =IF(M24>0,M24/E24,0) -> 0 | O24: =IF(N24=1,"SI","NO") -> NO
B25: VACIADO DE ZAPATAS | C25: m3 | N25: =IF(M25>0,M25/E25,0) -> 0 | O25: =IF(N25=1,"SI","NO") -> NO
B26: ENCOFRADO DE PLACAS | C26: m2 | N26: =IF(M26>0,M26/E26,0) -> 0 | O26: =IF(N26=1,"SI","NO") -> NO
N27: =IF(M27>0,M27/E27,0) -> 0 | O27: =IF(N27=1,"SI","NO") -> NO
Q29: CALCULO DE PPC
Q30: ACTIVIDADES CUMPLIDAS (100%) | R30: =COUNTIF($O$7:$O$27,"SI") -> 0
Q31: ACTIVIDADES NO CUMPLIDAS | R31: =COUNTIF($O$7:$O$27,"NO") -> 19
Q32: ACTIVIDADES PROGRAMADAS | R32: =R30+R31 -> 19
Q33: % DE CUMPLIMIENTO (PPC) | R33: =R30/R32 -> 0
P37: CAUSAS DE INCUMPLIMIENTO
P38: COD | Q38: DESCRIPCION | R38: CANT
P39: CLI-MAT | Q39: CLIENTE - MATERIALES | R39: =COUNTIF($V$10:$V$61,P39) -> 0
P40: CLI-ING | Q40: CLIENTE - INGENIERÍA | R40: =COUNTIF($V$10:$V$61,P40) -> 0
P41: CLI-PRI | Q41: CLIENTE - PRIORIDADES | R41: =COUNTIF($V$10:$V$61,P41) -> 0
P42: CLI-CAM | Q42: CLIENTE - CAMBIO | R42: =COUNTIF($V$10:$V$61,P42) -> 0
P43: MAT | Q43: MATERIALES | R43: =COUNTIF($V$10:$V$61,P43) -> 0
P44: DT | Q44: DOCUMENTACION TECNICA | R44: =COUNTIF($V$10:$V$61,P44) -> 0
P45: AP | Q45: ACTIVIDADES PREVIAS | R45: =COUNTIF($V$10:$V$61,P45) -> 0
...

Sheet H PPC
C1: ANÁLISIS PPC
W2: Fecha de corte : | X2: 43853
B3: 1 | C3: % de cumplimiento General del proyecto
C5: % cumplimiento | D5: =AVERAGE(F10:F26) -> #DIV/0!
B7: 2 | C7: Historico de % semanal de cumplimiento en PPC
C9: SEMANA | D9: Actividades planificadas | E9: Actividades completadas | F9: %
C10: 1 | D10: ='PPC S1'!R32 -> 19 | E10: ='PPC S1'!R30 -> 0 | F10: =E10/D10 -> 0
C11: =C10+1 -> 2 | F11: =E11/D11 -> #DIV/0!
C12: =C11+1 -> 3 | F12: =E12/D12 -> #DIV/0!
C13: =C12+1 -> 4 | F13: =E13/D13 -> #DIV/0!
C14: =C13+1 -> 5 | F14: =E14/D14 -> #DIV/0!
C15: =C14+1 -> 6 | F15: =E15/D15 -> #DIV/0!
C16: =C15+1 -> 7 | F16: =E16/D16 -> #DIV/0!
C17: =C16+1 -> 8 | F17: =E17/D17 -> #DIV/0!
C18: =C17+1 -> 9 | F18: =E18/D18 -> #DIV/0!
C19: =C18+1 -> 10 | F19: =E19/D19 -> #DIV/0!
C20: =C19+1 -> 11 | F20: =E20/D20 -> #DIV/0!
C21: =C20+1 -> 12 | F21: =E21/D21 -> #DIV/0!
C22: =C21+1 -> 13 | F22: =E22/D22 -> #DIV/0!
... C26: =C25+1 -> 17 | F26: =E26/D26 -> #DIV/0!
B29: 3 | C29: Causas de incumplimiento Historico
C31: Semana | D31: TIPO | E31: RESPONSABLE | F31: DESCRIPCION
C32: 1 | D32: CLI-ING | E32: CLIENTE | F32: =INDEX($D$38:$D$51,MATCH(D32,$C$38:$C$51,0)) -> CLIENTE - INGENIERÍA
C33: 1 | D33: CLI-ING | E33: CLIENTE | F33: =INDEX($D$38:$D$51,MATCH(D33,$C$38:$C$51,0)) -> CLIENTE - INGENIERÍA
C34: 4 | D34: DT | E34: CONSTRUCTOR | F34: =INDEX($D$38:$D$51,MATCH(D34,$C$38:$C$51,0)) -> DOCUMENTACION TECNICA
C37: COD | D37: DESCRIPCION | F37: CANTIDAD
C38: CLI-MAT | D38: CLIENTE - MATERIALES | F38: =COUNTIF($D$32:$D$34,C38) -> 0
C39: CLI-ING | D39: CLIENTE - INGENIERÍA | F39: =COUNTIF($D$32:$D$34,C39) -> 2
C40: CLI-PRI | D40: CLIENTE - PRIORIDADES | F40: =COUNTIF($D$32:$D$34,C40) -> 0
C41: CLI-CAM | D41: CLIENTE - CAMBIO | F41: =COUNTIF($D$32:$D$34,C41) -> 0
C42: MAT | D42: MATERIALES | F42: =COUNTIF($D$32:$D$34,C42) -> 0
C43: DT | D43: DOCUMENTACION TECNICA | F43: =COUNTIF($D$32:$D$34,C43) -> 1
C44: AP | D44: ACTIVIDADES PREVIAS | F44: =COUNTIF($D$32:$D$34,C44) -> 0
C45: EXT | D45: EXTERNO | F45: =COUNTIF($D$32:$D$34,C45) -> 0
C46: EE | D46: ERRORES DE EJECUCION | F46: =COUNTIF($D$32:$D$34,C46) -> 0
C47: QC | D47: CONTROL DE CALIDAD | F47: =COUNTIF($D$32:$D$34,C47) -> 0
C48: PER | D48: PERSONAL | F48: =COUNTIF($D$32:$D$34,C48) -> 0
C49: EQ | D49: EQUIPOS | F49: =COUNTIF($D$32:$D$34,C49) -> 0
... C51: IOF | D51: INCUMPLIMIENTO DE OTRO FRENTE | F51: =COUNTIF($D$32:$D$34,C51) -> 0
D52: TOTAL | F52: =SUM(F38:F51) -> 3

Sheet Flujo de caja
B1: FLUJO DE CAJA OBRA SURQUILLO
A5: MONTO ADJUDICADO DE OBRA | B5: 370000 | C5: INC IGV
A7: INGRESOS | B7: TOTAL | C7: 46167 | D7: =+C7+7 -> 46174 | E7: =+D7+7 -> 46181 | F7: =+E7+7 -> 46188 | G7: =+F7+7 -> 46195
C8: =+C7+5 -> 46172 | D8: =+D7+5 -> 46179 | E8: =+E7+5 -> 46186 | F8: =+F7+5 -> 46193 | G8: =+G7+5 -> 46200
C9: Sem 01 | D9: Sem 02 | E9: Sem 03 | F9: Sem 04 | G9: Sem 05
A10: Adelanto de obra | B10: =SUM(C10:G10) -> 0
A11: Valorizaciones | B11: =SUM(C11:G11) -> 0
A12: TOTAL DE INGRESOS | B12: =SUM(B10:B11) -> 0 | C12: =SUM(C10:C11) -> 0 | D12: =SUM(D10:D11) -> 0 | E12: =SUM(E10:E11) -> 0 | F12: =SUM(F10:F11) -> 0 | G12: =SUM(G10:G11) -> 0
A14: EGRESOS | B14: TOTAL | C14: =+C7 -> 46167 | D14: =+C14+7 -> 46174 | E14: =+D14+7 -> 46181 | F14: =+E14+7 -> 46188 | G14: =+F14+7 -> 46195
C15: =+C14+5 -> 46172 | D15: =+D14+5 -> 46179 | E15: =+E14+5 -> 46186 | F15: =+F14+5 -> 46193 | G15: =+G14+5 -> 46200
C16: Sem 01 | D16: Sem 02 | E16: Sem 03 | F16: Sem 04 | G16: Sem 05
A17: COSTO DIRECTO
A18: Costo Materiales y otros
A19: Seguridad y salud | B19: =SUM(C19:G19) -> 0
A20: Movimiento de tierras
A21: Eliminación de desmonte | B21: =SUM(C21:G21) -> 0
A22: Subcontrato de Demolición
A23: Adelanto de desmontaje | B23: =SUM(C23:G23) -> 0
A24: Mano de Obra y equipos | B24: =SUM(C24:G24) -> 0
A25: Subcontrato de Obra gruesa
A26: Adelanto de subcontratista | B26: =SUM(C26:G26) -> 0
A27: Mano de Obra y equipos | B27: =SUM(C27:G27) -> 0
A28: TOTAL COSTO INDIRECTO | B28: =SUM(B18:B24) -> 0 | C28: =SUM(C18:C24) -> 0 | D28: =SUM(D18:D24) -> 0 | E28: =SUM(E18:E24) -> 0 | F28: =SUM(F18:F24) -> 0 | G28: =SUM(G18:G24) -> 0
A30: COSTO INDIRECTO
A31: Residente de Obra | B31: =SUM(C31:G31) -> 0
A32: Seguros y polizas | B32: =SUM(C32:G32) -> 0
A33: Gastos varios | B33: =SUM(C33:G33) -> 0
A34: COSTO DIRECTO | B34: =SUM(B31:B33) -> 0 | C34: =SUM(C31:C33) -> 0 | D34: =SUM(D31:D33) -> 0 | E34: =SUM(E31:E33) -> 0 | F34: =SUM(F31:F33) -> 0 | G34: =SUM(G31:G33) -> 0
A35: TOTAL DE EGRESOS | B35: =+B34+B28 -> 0 | C35: =+C34+C28 -> 0 | E35: =+E34+E28 -> 0 | F35: =+F34+F28 -> 0
A37: SALDO OPERATIVO | B37: =+B12-B35 -> 0 | C37: =+C12-C35 -> 0 | D37: =+D12-D35 -> 0 | E37: =+E12-E35 -> 0 | F37: =+F12-F35 -> 0 | G37: =+G12-G35 -> 0

Sheet Depositos
A1: MONTO DE CONTRATO DE OBRA = | C1: 370000 | D1: A suma alzada
A3: Descripción | B3: Fecha | C3: Monto | D3: Cuenta
A4: ADELANTO TOTAL | C4: =SUM(C5:C5) -> 50000 | D4: =+C4/C1 -> 0.13513514
A5: Adelanto de obra 1 | B5: 46119 | C5: 50000 | D5: Cuenta dolares Guillermo Casallo
A6: VALORIZACIONES | C6: =SUM(C7:C11) -> 0 | D6: =+C6/C1 -> 0
A7: Semana 01
A8: Semana 02
A9: Semana 03
A10: Semana 04
A11: Semana 05
A12: Depósito total = | C12: =+C4+C6 -> 50000 | D12: =+C12/C1 -> 0.13513514
A13: Saldo de obra = | C13: =+C1-C12 -> 320000 | D13: =+C13/C1 -> 0.86486486
A16: MONTO DE SUBCONTRATO = | C16: 100000 | D16: Mano de obra casco gris
A18: Descripción | B18: Fecha | C18: Monto | D18: Cuenta
A19: ADELANTO TOTAL | C19: =SUM(C20:C21) -> 0 | D19: =+C19/C16 -> 0
A22: Descripción | B22: Fecha | C22: Monto | D22: Cuenta
A23: VALORIZACIONES | C23: =SUM(C24:C37) -> 0 | D23: =+C23/C16 -> 0
A24: Semana 01
A25: Semana 02
A26: Semana 03
A27: Semana 04
A28: Semana 05
A29: Semana 06
A30: Semana 07
A31: Semana 08
A32: Semana 09
A33: Semana 10
A34: Semana 11
A35: Semana 12
... A37: Semana 14
B38: TOTAL PAGADO | C38: =+C23+C19 -> 0 | D38: =+C38/C16 -> 0
B39: SALDO | C39: =+C16-C38 -> 100000 | D39: =+C39/C16 -> 1

Sheet Presupuesto Real Comparativo
A1: PRESUPUESTO DE OBRA POR PARTIDAS
A2: PROYECTO:
A3: PROPIETARIO(S) :
A4: UBICACIÓN:
A5: ITEM | B5: DESCRIPCIÓN DE PARTIDAS | C5: PRESUPUESTO ACTUAL
C6: UND | D6: METRADO | E6: PRECIO MO | F6: PRECIO PARCIAL MO | G6: PRECIO MAT | H6: PRECIO PARCIAL MAT | I6: PRECIO UNITARIO | J6: PRECIO PARCIAL
D7: CONTRATO
A8: =+'O. GRUESA'!A7 -> 01.00.00.00 | B8: =+'O. GRUESA'!B7 -> OBRAS PROVISIONALES, TRABAJOS PRELIMINARES, SEGURIDAD Y SALUD | F8: =+F9+F14+F20 -> 8112.842 | H8: =+H9+H14+H20 -> 15358.89 | J8: =+J9+J14+J20 -> 46869.445
A9: =+'O. GRUESA'!A8 -> 01.01.00.00 | B9: =+'O. GRUESA'!B8 -> OBRAS PROVISIONALES | F9: =SUM(F10:F13) -> 1167.265 | H9: =SUM(H10:H13) -> 9699.3875 | J9: =+RESUMEN!C4 -> 10876.107
A10: 01.01.01.00 | B10: =+'O. GRUESA'!B9 -> TRANSPORTE DE EQUIPOS Y HERRAMIENTAS | C10: =+'O. GRUESA'!D9 -> glb | D10: =+'O. GRUESA'!J9 -> 1 | E10: 1000 | F10: =D10*E10 -> 1000 | G10: 1000 | H10: =D10*G10 -> 1000 | I10: =+E10+G10 -> 2000 | J10: =D10*I10 -> 2000
A11: 01.01.02.00 | B11: =+'O. GRUESA'!B12 -> CERCO PERIMETRICO PROVISIONAL | C11: =+'O. GRUESA'!D12 -> ml | D11: =+'O. GRUESA'!J12 -> 30 | E11: 0 | F11: =D11*E11 -> 0 | G11: =+'APUs Casco'!F59+'APUs Casco'!F63+'APUs Casco'!F68 -> 157.89625 | H11: =D11*G11 -> 4736.8875 | I11: =+E11+G11 -> 157.89625 | J11: =D11*I11 -> 4736.8875
A12: 01.01.03.00 | B12: =+'O. GRUESA'!B15 -> PROTECCIÓN CON MALLA RASCHELL | C12: =+'O. GRUESA'!D15 -> ml | D12: =+'O. GRUESA'!J15 -> 180 | E12: =+'APUs Casco'!F74+'APUs Casco'!F82 -> 0.92925 | F12: =D12*E12 -> 167.265 | G12: =+'APUs Casco'!F78 -> 13.125 | H12: =D12*G12 -> 2362.5 | I12: =+E12+G12 -> 14.05425 | J12: =D12*I12 -> 2529.765
A13: 01.01.04.00 | B13: =+'O. GRUESA'!B21 -> ALQUILER DE BAÑO PROVISIONAL | C13: =+'O. GRUESA'!D21 -> mes | D13: =+'O. GRUESA'!J21 -> 4 | E13: 0 | F13: =D13*E13 -> 0 | G13: 400 | H13: =D13*G13 -> 1600 | I13: =+E13+G13 -> 400 | J13: =D13*I13 -> 1600
A14: =+'O. GRUESA'!A24 -> 01.02.00.00 | B14: =+'O. GRUESA'!B24 -> DEMOLICIÓN Y TRABAJOS PRELIMINARES | F14: =SUM(F15:F19) -> 3345.577 | H14: =SUM(H15:H19) -> 3209.502 | J14: =+RESUMEN!C5 -> 28571.36
A15: 01.02.01.00 | B15: =+'O. GRUESA'!B25 -> DESMONTAJE Y ACARREO DE MATERIAL | C15: =+'O. GRUESA'!D25 -> glb | D15: =+'O. GRUESA'!J25 -> 1 | E15: 1500 | F15: =D15*E15 -> 1500 | G15: 0 | H15: =D15*G15 -> 0 | I15: 3000 | J15: =D15*I15 -> 3000
A16: 01.02.02.00 | B16: APUNTALAMIENTO ESTRUCTURAL | C16: GLB | D16: 1 | E16: 0 | F16: =D16*E16 -> 0 | G16: 0 | H16: =D16*G16 -> 0 | I16: 2500 | J16: =D16*I16 -> 2500
A17: 01.02.03.00 | B17: DEMOLICIÓN MANUAL CON ROTOMARTILLO 3 PISOS Y AZOTEA | C17: =+'O. GRUESA'!D28 -> glb | D17: =+'O. GRUESA'!J28 -> 1 | E17: 0 | F17: =D17*E17 -> 0 | G17: 0 | H17: =D17*G17 -> 0 | I17: 18000 | J17: =D17*I17 -> 18000
A18: 01.02.04.00 | B18: =+'O. GRUESA'!B34 -> ELIMINACIÓN DE ESCOMBROS, DESMONTE | C18: =+'O. GRUESA'!D34 -> glb | D18: =+'O. GRUESA'!J34 -> 1 | E18: 0 | F18: =D18*E18 -> 0 | G18: 3000 | H18: =D18*G18 -> 3000 | I18: 3000 | J18: =D18*I18 -> 3000
A19: 01.02.05.00 | B19: =+'O. GRUESA'!B40 -> TRAZADO Y REPLANTEO S/EQUIPO | C19: =+'O. GRUESA'!D40 -> m2 | D19: 206 | E19: =+'APUs Casco'!F23+'APUs Casco'!F31 -> 8.9591117 | F19: =D19*E19 -> 1845.577 | G19: =+'APUs Casco'!F27 -> 1.017 | H19: =D19*G19 -> 209.502 | I19: =+J19/D19 -> 10.055146 | J19: =+J14-SUM(J15:J18) -> 2071.36
A20: =+'O. GRUESA'!A43 -> 01.03.00.00 | B20: =+'O. GRUESA'!B43 -> SEGURIDAD Y SALUD | F20: =SUM(F21:F24) -> 3600 | H20: =SUM(H21:H24) -> 2450 | J20: =+RESUMEN!C7 -> 7421.9785
A21: =+'O. GRUESA'!A44 -> 01.03.01.00 | B21: =+'O. GRUESA'!B44 -> EQUIPOS DE PROTECCIÓN INDIVIDUAL | C21: =+'O. GRUESA'!D44 -> und | D21: 30 | E21: 120 | F21: =D21*E21 -> 3600 | G21: 30 | H21: =D21*G21 -> 900 | I21: =+E21+G21 -> 150 | J21: =D21*I21 -> 4500
A22: =+'O. GRUESA'!A47 -> 01.03.02.00 | B22: =+'O. GRUESA'!B47 -> EQUIPOS DE PROTECCIÓN COLECTIVA | C22: =+'O. GRUESA'!D47 -> glb | D22: =+'O. GRUESA'!J47 -> 1 | E22: 0 | F22: =D22*E22 -> 0 | G22: 500 | H22: =D22*G22 -> 500 | I22: =+J22 -> 1071.9785 | J22: =+J20-J21-J23-J24 -> 1071.9785
A23: =+'O. GRUESA'!A50 -> 01.03.03.00 | B23: =+'O. GRUESA'!B50 -> SEÑALIZACIÓN TEMPORAL DE SEGURIDAD | C23: =+'O. GRUESA'!D50 -> glb | D23: =+'O. GRUESA'!J50 -> 1 | E23: 0 | F23: =D23*E23 -> 0 | G23: 250 | H23: =D23*G23 -> 250 | I23: =+E23+G23 -> 250 | J23: =D23*I23 -> 250
A24: =+'O. GRUESA'!A53 -> 01.03.04.00 | B24: =+'O. GRUESA'!B53 -> SEGURO SCTR | C24: =+'O. GRUESA'!D53 -> mes | D24: =+'O. GRUESA'!J53 -> 4 | E24: 0 | F24: =D24*E24 -> 0 | G24: 200 | H24: =D24*G24 -> 800 | I24: 400 | J24: =D24*I24 -> 1600
A25: =+'O. GRUESA'!A56 -> 02.00.00.00 | B25: =+'O. GRUESA'!B56 -> MOVIMIENTO DE TIERRAS | F25: =SUM(F26:F30) -> 5964.1277 | H25: =SUM(H26:H30) -> 2253.3181 | J25: =+RESUMEN!C6 -> 7667.9579
A26: 02.01.00.00 | B26: ='O. GRUESA'!$B$57 -> EXCAVACIÓN MANUAL P/CIMIENTO Y ZAPATA | C26: ='O. GRUESA'!$D$57 -> m3 | D26: ='O. GRUESA'!$J$57 -> 54.705 | E26: ='APUs Casco'!$F$131 -> 45.888889 | F26: =D26*E26 -> 2510.3517 | G26: ='APUs Casco'!$F$134 -> 1.3766667 | H26: =D26*G26 -> 75.31055 | I26: =+J26/D26 -> 37.220991 | J26: =+J25-SUM(J27:J30) -> 2036.1743
A27: 02.02.00.00 | B27: =+'O. GRUESA'!B74 -> COMPACTACIÓN MANUAL P/CIMIENTO Y ZAPATA | C27: =+'O. GRUESA'!D74 -> m2 | D27: =+'O. GRUESA'!J74 -> 33.045 | E27: =+'APUs Casco'!F140 -> 23.993333 | F27: =D27*E27 -> 792.8597 | G27: =+'APUs Casco'!F144 -> 3.1198 | H27: =D27*G27 -> 103.09379 | I27: =+E27+G27 -> 27.113133 | J27: =D27*I27 -> 895.95349
A28: 02.03.00.00 | B28: =+'O. GRUESA'!B91 -> RELLENO COMPACTADO CON MATERIAL PROPIO | C28: =+'O. GRUESA'!D91 -> m3 | D28: =+'O. GRUESA'!J91 -> 28.584 | E28: =+'APUs Casco'!F151 -> 0.68833333 | F28: =D28*E28 -> 19.67532 | G28: =+'APUs Casco'!F154 -> 5.0344167 | H28: =D28*G28 -> 143.90377 | I28: =+E28+G28 -> 5.72275 | J28: =D28*I28 -> 163.57909
A29: 02.04.00.00 | B29: =+'O. GRUESA'!B108 -> ELIMINACION DE MATERIAL CON MAQUINARIA | C29: =+'O. GRUESA'!D108 -> m3 | D29: =+'O. GRUESA'!J108 -> 54.705 | E29: =+'APUs Casco'!F184 -> 7.8666667 | F29: =D29*E29 -> 430.346 | G29: 22 | H29: =D29*G29 -> 1203.51 | I29: =+E29+G29 -> 29.866667 | J29: =D29*I29 -> 1633.856
A30: 02.05.00.00 | B30: =+'O. GRUESA'!B112 -> NIVELACION DE TERRENO Y APISONADO C/20 CM. | C30: =+'O. GRUESA'!D112 -> m2 | D30: =+'O. GRUESA'!J112 -> 150 | E30: =+'APUs Casco'!F193+'APUs Casco'!F201 -> 14.7393 | F30: =D30*E30 -> 2210.895 | G30: =+'APUs Casco'!F198 -> 4.85 | H30: =D30*G30 -> 727.5 | I30: =+E30+G30 -> 19.5893 | J30: =D30*I30 -> 2938.395
A31: =+'O. GRUESA'!A116 -> 03.00.00.00 | B31: =+'O. GRUESA'!B116 -> 1ER PISO | F31: =+F32+F42+F70+F73 -> 50087.853 | H31: =+H32+H42+H70+H73 -> 55039.907 | J31: =+J32+J42+J70+J73+J82+J90 -> 129861.17
A32: 03.01.00.00 | B32: =+'O. GRUESA'!B117 -> CONCRETO SIMPLE | F32: =SUM(F33:F41) -> 6290.3482 | H32: =SUM(H33:H41) -> 10936.765 | J32: =+RESUMEN!C9 -> 17227.114
A33: 03.01.01.00 | B33: SOLADO
A34: 03.01.01.01 | B34: =+'O. GRUESA'!B119 -> CONCRETO, fc=100 kg/cm² | C34: =+'O. GRUESA'!D119 -> m2 | D34: =+'O. GRUESA'!J119 -> 17.67 | E34: =+'APUs Casco'!F208+'APUs Casco'!F217 -> 14.642056 | F34: =D34*E34 -> 258.72512 | G34: =+'APUs Casco'!F214 -> 28.775 | H34: =D34*G34 -> 508.45425 | I34: =+E34+G34 -> 43.417056 | J34: =D34*I34 -> 767.17937
A35: 03.01.02.00 | B35: =+'O. GRUESA'!B124 -> CIMIENTO CORRIDO
A36: 03.01.02.01 | B36: =+'O. GRUESA'!B125 -> CONCRETO f'c= 100 kg/cm² +30% P.G. (Tamaño maximo 6") | C36: =+'O. GRUESA'!D125 -> m3 | D36: =+'O. GRUESA'!J125 -> 18.45 | E36: =+'APUs Casco'!F300+'APUs Casco'!F309 -> 73.423111 | F36: =D36*E36 -> 1354.6564 | G36: =+'APUs Casco'!F305 -> 312.85 | H36: =D36*G36 -> 5772.0825 | I36: =+E36+G36 -> 386.27311 | J36: =D36*I36 -> 7126.7389
A37: 03.01.03.00 | B37: =+'O. GRUESA'!B139 -> SOBRECIMIENTO
A38: 03.01.03.01 | B38: =+'O. GRUESA'!B140 -> CONCRETO, f'c= 140 kg/cm² +25% P.M. (Tamaño maximo 3") | C38: =+'O. GRUESA'!D140 -> m3 | D38: =+'O. GRUESA'!J140 -> 2.74875 | E38: =+'APUs Casco'!F330+'APUs Casco'!F339 -> 110.13467 | F38: =D38*E38 -> 302.73267 | G38: =+'APUs Casco'!F335 -> 250.85 | H38: =D38*G38 -> 689.52394 | I38: =+E38+G38 -> 360.98467 | J38: =D38*I38 -> 992.2566
A39: 03.01.03.02 | B39: =+'O. GRUESA'!B154 -> ENCOFRADO Y DESENCOFRADO | C39: =+'O. GRUESA'!D154 -> m2 | D39: =+'O. GRUESA'!J154 -> 36.65 | E39: =+'APUs Casco'!F316+'APUs Casco'!F324 -> 35.449167 | F39: =D39*E39 -> 1299.212 | G39: =+'APUs Casco'!F321 -> 2.1 | H39: =D39*G39 -> 76.965 | I39: =+E39+G39 -> 37.549167 | J39: =D39*I39 -> 1376.177
A40: 03.01.04.00 | B40: =+'O. GRUESA'!B168 -> FALSO PISO
...

Sheet Valorización
A1: PRESUPUESTO DE OBRA POR PARTIDAS
A2: PROYECTO:
A3: PROPIETARIO(S) :
A4: UBICACIÓN:
A5: ITEM | B5: DESCRIPCIÓN DE PARTIDAS | C5: PRESUPUESTO ACTUAL | K5: VALORIZACIÓN | Q5: SALDO
C6: UND | D6: METRADO | E6: PRECIO MO | F6: PRECIO PARCIAL MO | G6: PRECIO MAT | H6: PRECIO PARCIAL MAT | I6: PRECIO UNITARIO | J6: PRECIO PARCIAL | K6: ACUMULADO ANTERIOR | M6: AVANCE ACTUAL | O6: ACUMULADO ACTUAL
D7: CONTRATO | K7: % | L7: PRECIO | M7: % | N7: PRECIO | O7: % | P7: PRECIO | Q7: % | R7: PRECIO
A8: =+'O. GRUESA'!A7 -> 01.00.00.00 | B8: =+'O. GRUESA'!B7 -> OBRAS PROVISIONALES, TRABAJOS PRELIMINARES, SEGURIDAD Y SALUD | F8: =+F9+F14+F20 -> 8112.842 | H8: =+H9+H14+H20 -> 15358.89 | J8: =+J9+J14+J20 -> 46869.445 | L8: =+L9+L14+L20 -> 0 | N8: =+N9+N14+N20 -> 14338.631 | P8: =+P9+P14+P20 -> 14338.631 | R8: =+R9+R14+R20 -> 32521.36
A9: =+'O. GRUESA'!A8 -> 01.01.00.00 | B9: =+'O. GRUESA'!B8 -> OBRAS PROVISIONALES | F9: =SUM(F10:F13) -> 1167.265 | H9: =SUM(H10:H13) -> 9699.3875 | J9: =+RESUMEN!C4 -> 10876.107 | L9: =SUM(L10:L13) -> 0 | N9: =SUM(N10:N13) -> 8266.6525 | P9: =SUM(P10:P13) -> 8266.6525 | R9: =SUM(R10:R13) -> 2600
A10: 01.01.01.00 | B10: =+'O. GRUESA'!B9 -> TRANSPORTE DE EQUIPOS Y HERRAMIENTAS | C10: =+'O. GRUESA'!D9 -> glb | D10: =+'O. GRUESA'!J9 -> 1 | E10: 1000 | F10: =D10*E10 -> 1000 | G10: 1000 | H10: =D10*G10 -> 1000 | I10: =+E10+G10 -> 2000 | J10: =D10*I10 -> 2000 | L10: =+J10*K10 -> 0 | M10: 0.5 | N10: =+M10*J10 -> 1000 | O10: =+K10+M10 -> 0.5 | P10: =+N10+L10 -> 1000 | Q10: =100%-O10 -> 0.5 | R10: =+J10-P10 -> 1000
A11: 01.01.02.00 | B11: =+'O. GRUESA'!B12 -> CERCO PERIMETRICO PROVISIONAL | C11: =+'O. GRUESA'!D12 -> ml | D11: =+'O. GRUESA'!J12 -> 30 | E11: 0 | F11: =D11*E11 -> 0 | G11: 157.89625 | H11: =D11*G11 -> 4736.8875 | I11: =+E11+G11 -> 157.89625 | J11: =D11*I11 -> 4736.8875 | L11: =+J11*K11 -> 0 | M11: 1 | N11: =+M11*J11 -> 4736.8875 | O11: =+K11+M11 -> 1 | P11: =+N11+L11 -> 4736.8875 | Q11: =100%-O11 -> 0 | R11: =+J11-P11 -> 0
A12: 01.01.03.00 | B12: =+'O. GRUESA'!B15 -> PROTECCIÓN CON MALLA RASCHELL | C12: =+'O. GRUESA'!D15 -> ml | D12: =+'O. GRUESA'!J15 -> 180 | E12: 0.92925 | F12: =D12*E12 -> 167.265 | G12: 13.125 | H12: =D12*G12 -> 2362.5 | I12: =+E12+G12 -> 14.05425 | J12: =D12*I12 -> 2529.765 | L12: =+J12*K12 -> 0 | M12: 1 | N12: =+M12*J12 -> 2529.765 | O12: =+K12+M12 -> 1 | P12: =+N12+L12 -> 2529.765 | Q12: =100%-O12 -> 0 | R12: =+J12-P12 -> 0
A13: 01.01.04.00 | B13: =+'O. GRUESA'!B21 -> ALQUILER DE BAÑO PROVISIONAL | C13: =+'O. GRUESA'!D21 -> mes | D13: =+'O. GRUESA'!J21 -> 4 | E13: 0 | F13: =D13*E13 -> 0 | G13: 400 | H13: =D13*G13 -> 1600 | I13: =+E13+G13 -> 400 | J13: =D13*I13 -> 1600 | L13: =+J13*K13 -> 0 | N13: =+M13*J13 -> 0 | O13: =+K13+M13 -> 0 | P13: =+N13+L13 -> 0 | Q13: =100%-O13 -> 1 | R13: =+J13-P13 -> 1600
A14: =+'O. GRUESA'!A24 -> 01.02.00.00 | B14: =+'O. GRUESA'!B24 -> DEMOLICIÓN Y TRABAJOS PRELIMINARES | F14: =SUM(F15:F19) -> 3345.577 | H14: =SUM(H15:H19) -> 3209.502 | J14: =+RESUMEN!C5 -> 28571.36 | L14: =SUM(L15:L19) -> 0 | N14: =SUM(N15:N19) -> 3000 | P14: =SUM(P15:P19) -> 3000 | R14: =SUM(R15:R19) -> 25571.36
A15: 01.02.01.00 | B15: =+'O. GRUESA'!B25 -> DESMONTAJE Y ACARREO DE MATERIAL | C15: =+'O. GRUESA'!D25 -> glb | D15: =+'O. GRUESA'!J25 -> 1 | E15: 1500 | F15: =D15*E15 -> 1500 | G15: 0 | H15: =D15*G15 -> 0 | I15: 3000 | J15: =D15*I15 -> 3000 | L15: =+J15*K15 -> 0 | M15: 1 | N15: =+M15*J15 -> 3000 | O15: =+K15+M15 -> 1 | P15: =+N15+L15 -> 3000 | Q15: =100%-O15 -> 0 | R15: =+J15-P15 -> 0
A16: 01.02.02.00 | B16: APUNTALAMIENTO ESTRUCTURAL | C16: GLB | D16: 1 | E16: 0 | F16: =D16*E16 -> 0 | G16: 0 | H16: =D16*G16 -> 0 | I16: 2500 | J16: =D16*I16 -> 2500 | L16: =+J16*K16 -> 0 | N16: =+M16*J16 -> 0 | O16: =+K16+M16 -> 0 | P16: =+N16+L16 -> 0 | Q16: =100%-O16 -> 1 | R16: =+J16-P16 -> 2500
A17: 01.02.03.00 | B17: DEMOLICIÓN MANUAL CON ROTOMARTILLO 3 PISOS Y AZOTEA | C17: =+'O. GRUESA'!D28 -> glb | D17: =+'O. GRUESA'!J28 -> 1 | E17: 0 | F17: =D17*E17 -> 0 | G17: 0 | H17: =D17*G17 -> 0 | I17: 18000 | J17: =D17*I17 -> 18000 | L17: =+J17*K17 -> 0 | N17: =+M17*J17 -> 0 | O17: =+K17+M17 -> 0 | P17: =+N17+L17 -> 0 | Q17: =100%-O17 -> 1 | R17: =+J17-P17 -> 18000
A18: 01.02.04.00 | B18: =+'O. GRUESA'!B34 -> ELIMINACIÓN DE ESCOMBROS, DESMONTE | C18: =+'O. GRUESA'!D34 -> glb | D18: =+'O. GRUESA'!J34 -> 1 | E18: 0 | F18: =D18*E18 -> 0 | G18: 3000 | H18: =D18*G18 -> 3000 | I18: 3000 | J18: =D18*I18 -> 3000 | L18: =+J18*K18 -> 0 | N18: =+M18*J18 -> 0 | O18: =+K18+M18 -> 0 | P18: =+N18+L18 -> 0 | Q18: =100%-O18 -> 1 | R18: =+J18-P18 -> 3000
A19: 01.02.05.00 | B19: =+'O. GRUESA'!B40 -> TRAZADO Y REPLANTEO S/EQUIPO | C19: =+'O. GRUESA'!D40 -> m2 | D19: 206 | E19: 8.9591117 | F19: =D19*E19 -> 1845.577 | G19: 1.017 | H19: =D19*G19 -> 209.502 | I19: =+J19/D19 -> 10.055146 | J19: =+J14-SUM(J15:J18) -> 2071.36 | L19: =+J19*K19 -> 0 | N19: =+M19*J19 -> 0 | O19: =+K19+M19 -> 0 | P19: =+N19+L19 -> 0 | Q19: =100%-O19 -> 1 | R19: =+J19-P19 -> 2071.36
A20: =+'O. GRUESA'!A43 -> 01.03.00.00 | B20: =+'O. GRUESA'!B43 -> SEGURIDAD Y SALUD | F20: =SUM(F21:F24) -> 3600 | H20: =SUM(H21:H24) -> 2450 | J20: =+RESUMEN!C7 -> 7421.9785 | L20: =SUM(L21:L24) -> 0 | N20: =SUM(N21:N24) -> 3071.9785 | P20: =SUM(P21:P24) -> 3071.9785 | R20: =SUM(R21:R24) -> 4350
A21: =+'O. GRUESA'!A44 -> 01.03.01.00 | B21: =+'O. GRUESA'!B44 -> EQUIPOS DE PROTECCIÓN INDIVIDUAL | C21: =+'O. GRUESA'!D44 -> und | D21: 30 | E21: 120 | F21: =D21*E21 -> 3600 | G21: 30 | H21: =D21*G21 -> 900 | I21: =+E21+G21 -> 150 | J21: =D21*I21 -> 4500 | L21: =+J21*K21 -> 0 | M21: 0.3 | N21: =+M21*J21 -> 1350 | O21: =+K21+M21 -> 0.3 | P21: =+N21+L21 -> 1350 | Q21: =100%-O21 -> 0.7 | R21: =+J21-P21 -> 3150
A22: =+'O. GRUESA'!A47 -> 01.03.02.00 | B22: =+'O. GRUESA'!B47 -> EQUIPOS DE PROTECCIÓN COLECTIVA | C22: =+'O. GRUESA'!D47 -> glb | D22: =+'O. GRUESA'!J47 -> 1 | E22: 0 | F22: =D22*E22 -> 0 | G22: 500 | H22: =D22*G22 -> 500 | I22: =+J22 -> 1071.9785 | J22: =+J20-J21-J23-J24 -> 1071.9785 | L22: =+J22*K22 -> 0 | M22: 1 | N22: =+M22*J22 -> 1071.9785 | O22: =+K22+M22 -> 1 | P22: =+N22+L22 -> 1071.9785 | Q22: =100%-O22 -> 0 | R22: =+J22-P22 -> 0
A23: =+'O. GRUESA'!A50 -> 01.03.03.00 | B23: =+'O. GRUESA'!B50 -> SEÑALIZACIÓN TEMPORAL DE SEGURIDAD | C23: =+'O. GRUESA'!D50 -> glb | D23: =+'O. GRUESA'!J50 -> 1 | E23: 0 | F23: =D23*E23 -> 0 | G23: 250 | H23: =D23*G23 -> 250 | I23: =+E23+G23 -> 250 | J23: =D23*I23 -> 250 | L23: =+J23*K23 -> 0 | M23: 1 | N23: =+M23*J23 -> 250 | O23: =+K23+M23 -> 1 | P23: =+N23+L23 -> 250 | Q23: =100%-O23 -> 0 | R23: =+J23-P23 -> 0
A24: =+'O. GRUESA'!A53 -> 01.03.04.00 | B24: =+'O. GRUESA'!B53 -> SEGURO SCTR | C24: =+'O. GRUESA'!D53 -> mes | D24: =+'O. GRUESA'!J53 -> 4 | E24: 0 | F24: =D24*E24 -> 0 | G24: 200 | H24: =D24*G24 -> 800 | I24: 400 | J24: =D24*I24 -> 1600 | L24: =+J24*K24 -> 0 | M24: 0.25 | N24: =+M24*J24 -> 400 | O24: =+K24+M24 -> 0.25 | P24: =+N24+L24 -> 400 | Q24: =100%-O24 -> 0.75 | R24: =+J24-P24 -> 1200
A25: =+'O. GRUESA'!A56 -> 02.00.00.00 | B25: =+'O. GRUESA'!B56 -> MOVIMIENTO DE TIERRAS | F25: =SUM(F26:F30) -> 5964.1277 | H25: =SUM(H26:H30) -> 2253.3181 | J25: =+RESUMEN!C6 -> 7667.9579 | L25: =SUM(L26:L30) -> 0 | N25: =SUM(N26:N30) -> 0 | P25: =SUM(P26:P30) -> 0 | R25: =SUM(R26:R30) -> 7667.9579
A26: 02.01.00.00 | B26: ='O. GRUESA'!$B$57 -> EXCAVACIÓN MANUAL P/CIMIENTO Y ZAPATA | C26: ='O. GRUESA'!$D$57 -> m3 | D26: ='O. GRUESA'!$J$57 -> 54.705 | E26: 45.888889 | F26: =D26*E26 -> 2510.3517 | G26: 1.3766667 | H26: =D26*G26 -> 75.31055 | I26: =+J26/D26 -> 37.220991 | J26: =+J25-SUM(J27:J30) -> 2036.1743 | L26: =+J26*K26 -> 0 | N26: =+M26*J26 -> 0 | O26: =+K26+M26 -> 0 | P26: =+N26+L26 -> 0 | Q26: =100%-O26 -> 1 | R26: =+J26-P26 -> 2036.1743
A27: 02.02.00.00 | B27: =+'O. GRUESA'!B74 -> COMPACTACIÓN MANUAL P/CIMIENTO Y ZAPATA | C27: =+'O. GRUESA'!D74 -> m2 | D27: =+'O. GRUESA'!J74 -> 33.045 | E27: 23.993333 | F27: =D27*E27 -> 792.8597 | G27: 3.1198 | H27: =D27*G27 -> 103.09379 | I27: =+E27+G27 -> 27.113133 | J27: =D27*I27 -> 895.95349 | L27: =+J27*K27 -> 0 | N27: =+M27*J27 -> 0 | O27: =+K27+M27 -> 0 | P27: =+N27+L27 -> 0 | Q27: =100%-O27 -> 1 | R27: =+J27-P27 -> 895.95349
A28: 02.03.00.00 | B28: =+'O. GRUESA'!B91 -> RELLENO COMPACTADO CON MATERIAL PROPIO | C28: =+'O. GRUESA'!D91 -> m3 | D28: =+'O. GRUESA'!J91 -> 28.584 | E28: 0.68833333 | F28: =D28*E28 -> 19.67532 | G28: 5.0344167 | H28: =D28*G28 -> 143.90377 | I28: =+E28+G28 -> 5.72275 | J28: =D28*I28 -> 163.57909 | L28: =+J28*K28 -> 0 | N28: =+M28*J28 -> 0 | O28: =+K28+M28 -> 0 | P28: =+N28+L28 -> 0 | Q28: =100%-O28 -> 1 | R28: =+J28-P28 -> 163.57909
A29: 02.04.00.00 | B29: =+'O. GRUESA'!B108 -> ELIMINACION DE MATERIAL CON MAQUINARIA | C29: =+'O. GRUESA'!D108 -> m3 | D29: =+'O. GRUESA'!J108 -> 54.705 | E29: 7.8666667 | F29: =D29*E29 -> 430.346 | G29: 22 | H29: =D29*G29 -> 1203.51 | I29: =+E29+G29 -> 29.866667 | J29: =D29*I29 -> 1633.856 | L29: =+J29*K29 -> 0 | N29: =+M29*J29 -> 0 | O29: =+K29+M29 -> 0 | P29: =+N29+L29 -> 0 | Q29: =100%-O29 -> 1 | R29: =+J29-P29 -> 1633.856
A30: 02.05.00.00 | B30: =+'O. GRUESA'!B112 -> NIVELACION DE TERRENO Y APISONADO C/20 CM. | C30: =+'O. GRUESA'!D112 -> m2 | D30: =+'O. GRUESA'!J112 -> 150 | E30: 14.7393 | F30: =D30*E30 -> 2210.895 | G30: 4.85 | H30: =D30*G30 -> 727.5 | I30: =+E30+G30 -> 19.5893 | J30: =D30*I30 -> 2938.395 | L30: =+J30*K30 -> 0 | N30: =+M30*J30 -> 0 | O30: =+K30+M30 -> 0 | P30: =+N30+L30 -> 0 | Q30: =100%-O30 -> 1 | R30: =+J30-P30 -> 2938.395
A31: =+'O. GRUESA'!A116 -> 03.00.00.00 | B31: =+'O. GRUESA'!B116 -> 1ER PISO | F31: =+F32+F42+F70+F73 -> 50087.853 | H31: =+H32+H42+H70+H73 -> 55039.907 | J31: =+J32+J42+J70+J73+J82+J90 -> 129861.17 | L31: =SUM(L33:L41) -> 0 | N31: =SUM(N33:N41) -> 0 | P31: =SUM(P33:P41) -> 0 | R31: =+J31-P31 -> 129861.17
A32: 03.01.00.00 | B32: =+'O. GRUESA'!B117 -> CONCRETO SIMPLE | F32: =SUM(F33:F41) -> 6290.3482 | H32: =SUM(H33:H41) -> 10936.765 | J32: =+RESUMEN!C9 -> 17227.114 | L32: =+RESUMEN!E9 -> 0
A33: 03.01.01.00 | B33: SOLADO | R33: =+J33-P33 -> 0
A34: 03.01.01.01 | B34: =+'O. GRUESA'!B119 -> CONCRETO, fc=100 kg/cm² | C34: =+'O. GRUESA'!D119 -> m2 | D34: =+'O. GRUESA'!J119 -> 17.67 | E34: 14.642056 | F34: =D34*E34 -> 258.72512 | G34: 28.775 | H34: =D34*G34 -> 508.45425 | I34: =+E34+G34 -> 43.417056 | J34: =D34*I34 -> 767.17937 | L34: =+J34*K34 -> 0 | N34: =+M34*J34 -> 0 | O34: =+K34+M34 -> 0 | P34: =+N34+L34 -> 0 | Q34: =100%-O34 -> 1 | R34: =+J34-P34 -> 767.17937
A35: 03.01.02.00 | B35: =+'O. GRUESA'!B124 -> CIMIENTO CORRIDO | R35: =+J35-P35 -> 0
A36: 03.01.02.01 | B36: =+'O. GRUESA'!B125 -> CONCRETO f'c= 100 kg/cm² +30% P.G. (Tamaño maximo 6") | C36: =+'O. GRUESA'!D125 -> m3 | D36: =+'O. GRUESA'!J125 -> 18.45 | E36: 73.423111 | F36: =D36*E36 -> 1354.6564 | G36: 312.85 | H36: =D36*G36 -> 5772.0825 | I36: =+E36+G36 -> 386.27311 | J36: =D36*I36 -> 7126.7389 | L36: =+J36*K36 -> 0 | N36: =+M36*J36 -> 0 | O36: =+K36+M36 -> 0 | P36: =+N36+L36 -> 0 | Q36: =100%-O36 -> 1 | R36: =+J36-P36 -> 7126.7389
A37: 03.01.03.00 | B37: =+'O. GRUESA'!B139 -> SOBRECIMIENTO | R37: =+J37-P37 -> 0
A38: 03.01.03.01 | B38: =+'O. GRUESA'!B140 -> CONCRETO, f'c= 140 kg/cm² +25% P.M. (Tamaño maximo 3") | C38: =+'O. GRUESA'!D140 -> m3 | D38: =+'O. GRUESA'!J140 -> 2.74875 | E38: 110.13467 | F38: =D38*E38 -> 302.73267 | G38: 250.85 | H38: =D38*G38 -> 689.52394 | I38: =+E38+G38 -> 360.98467 | J38: =D38*I38 -> 992.2566 | L38: =+J38*K38 -> 0 | N38: =+M38*J38 -> 0 | O38: =+K38+M38 -> 0 | P38: =+N38+L38 -> 0 | Q38: =100%-O38 -> 1 | R38: =+J38-P38 -> 992.2566
A39: 03.01.03.02 | B39: =+'O. GRUESA'!B154 -> ENCOFRADO Y DESENCOFRADO | C39: =+'O. GRUESA'!D154 -> m2 | D39: =+'O. GRUESA'!J154 -> 36.65 | E39: 35.449167 | F39: =D39*E39 -> 1299.212 | G39: 2.1 | H39: =D39*G39 -> 76.965 | I39: =+E39+G39 -> 37.549167 | J39: =D39*I39 -> 1376.177 | L39: =+J39*K39 -> 0 | N39: =+M39*J39 -> 0 | O39: =+K39+M39 -> 0 | P39: =+N39+L39 -> 0 | Q39: =100%-O39 -> 1 | R39: =+J39-P39 -> 1376.177
A40: 03.01.04.00 | B40: =+'O. GRUESA'!B168 -> FALSO PISO | R40: =+J40-P40 -> 0
...

Sheet O. GRUESA
A1: PLANILLA DE METRADO OBRA GRUESA
A2: PROYECTO: | B2: =Valorización!B2 -> 0
A3: PROPIETARIO(S) : | B3: =Valorización!B3 -> 0
A4: UBICACIÓN: | B4: LT 18 MZ DDF, JR. ALAMEDA EL ESPINEL, URB BRISAS DEL MAR - DISTRITO CHORRILLOS, DEPARTAMENTO Y PROVINCIA DE LIMA
A5: PARTIDA | B5: DESCRIPCION | D5: und | E5: CANT | F5: MEDIDAS | I5: PARCIAL | J5: TOTAL
F6: LARGO | G6: ANCHO | H6: ALTO
A7: 01.00.00.00 | B7: OBRAS PROVISIONALES, TRABAJOS PRELIMINARES, SEGURIDAD Y SALUD
A8: 01.01.00.00 | B8: OBRAS PROVISIONALES
A9: 01.01.01.00 | B9: TRANSPORTE DE EQUIPOS Y HERRAMIENTAS | D9: glb | J9: =SUM(I10:I11) -> 1 | K9: OK
E10: 1 | I10: =PRODUCT(E10:H10) -> 1
A12: 01.01.02.00 | B12: CERCO PERIMETRICO PROVISIONAL | D12: ml | J12: =SUM(I13:I14) -> 30 | K12: OK
E13: 1 | F13: PERIM= | G13: 30 | I13: =PRODUCT(E13:H13) -> 30
A15: 01.01.03.00 | B15: PROTECCIÓN CON MALLA RASCHELL | D15: ml | J15: =SUM(I16:I17) -> 180 | K15: OK
E16: 6 | F16: PERIM= | G16: 30 | I16: =PRODUCT(E16:H16) -> 180
A18: 01.01.04.00 | B18: INSTALACION DE OFICINA Y ALMACEN | D18: glb | J18: =SUM(I19:I20) -> 1 | K18: OK
E19: 1 | I19: =PRODUCT(E19:H19) -> 1
A21: 01.01.05.00 | B21: ALQUILER DE BAÑO PROVISIONAL | D21: mes | J21: =SUM(I22:I23) -> 4 | K21: OK
E22: 4 | F22: 1 | I22: =PRODUCT(E22:H22) -> 4
A24: 01.02.00.00 | B24: DEMOLICIÓN Y TRABAJOS PRELIMINARES
A25: 01.02.01.00 | B25: DESMONTAJE Y ACARREO DE MATERIAL | D25: glb | J25: =SUM(I26:I27) -> 1 | K25: OK
E26: 1 | I26: =PRODUCT(E26:H26) -> 1
A28: 01.02.02.00 | B28: DEMOLICIÓN MANUAL CON ROTOMARTILLO | D28: glb | J28: =SUM(I29:I30) -> 1 | K28: OK
E29: 1 | I29: =PRODUCT(E29:H29) -> 1
A31: 01.02.03.00 | B31: DEMOLICIÓN CON MAQUINARIA PESADA | D31: glb | J31: =SUM(I32:I33) -> 1 | K31: OK
E32: 1 | I32: =PRODUCT(E32:H32) -> 1
A34: 01.02.04.00 | B34: ELIMINACIÓN DE ESCOMBROS, DESMONTE | D34: glb | J34: =SUM(I35:I36) -> 1 | K34: OK
E35: 1 | I35: =PRODUCT(E35:H35) -> 1
A37: 01.02.05.00 | B37: LIMPIEZA DE TERRENO MANUAL | D37: m2 | J37: =SUM(I38:I39) -> 150 | K37: OK
B38: AREA DE TERRENO | D38: m2 | E38: 1 | F38: 5 | G38: 30 | I38: =PRODUCT(E38:H38) -> 150
A40: 01.02.06.00 | B40: TRAZADO Y REPLANTEO S/EQUIPO | D40: m2 | J40: =SUM(I41:I42) -> 150 | K40: OK
D41: m2 | E41: =+E38 -> 1 | F41: 5 | G41: 30 | I41: =PRODUCT(E41:H41) -> 150
A43: 01.03.00.00 | B43: SEGURIDAD Y SALUD
A44: 01.03.01.00 | B44: EQUIPOS DE PROTECCIÓN INDIVIDUAL | D44: und | J44: =SUM(I45:I46) -> 30 | K44: OK
E45: 30 | I45: =PRODUCT(E45:H45) -> 30
A47: 01.03.02.00 | B47: EQUIPOS DE PROTECCIÓN COLECTIVA | D47: glb | J47: =SUM(I48:I49) -> 1 | K47: OK
E48: 1 | I48: =PRODUCT(E48:H48) -> 1
A50: 01.03.03.00 | B50: SEÑALIZACIÓN TEMPORAL DE SEGURIDAD | D50: glb | J50: =SUM(I51:I52) -> 1 | K50: OK
E51: 1 | I51: =PRODUCT(E51:H51) -> 1
A53: 01.03.04.00 | B53: SEGURO SCTR | D53: mes | J53: =SUM(I54:I55) -> 4 | K53: OK
E54: 4 | I54: =PRODUCT(E54:H54) -> 4
...

Sheet ACERO
A1: PLANILLA DE METRADO: ACERO
A2: =Valorización!A2 -> PROYECTO: | B2: =Valorización!B2 -> 0
A3: =Valorización!A3 -> PROPIETARIO(S) : | B3: =Valorización!B3 -> 0
A4: =Valorización!A4 -> UBICACIÓN: | B4: LT 18 MZ DDF, JR. ALAMEDA EL ESPINEL, URB BRISAS DEL MAR - DISTRITO CHORRILLOS, DEPARTAMENTO Y PROVINCIA DE LIMA
A5: PARTIDA | B5: DESCRIPCION | D5: UNIDAD | E5: CANT | F5: DIAMETRO | G5: ESTRUTURAS | H5: LONGITUD
G6: IGUALES | I6: 6mm | J6: 8mm | K6: 3/8 | L6: 1/2 | M6: 5/8 | N6: 3/4 | O6: 1 | P6: TOTAL
B7: 1ER PISO
A8: 01.01.00 | B8: ACERO ASTM f'y = 4200 kg/cm2 EN ZAPATAS | P8: =SUM(I32:O32) -> 917.7074
B9: Z-1 | C9: EJE X | D9: KG | E9: 1 | F9: 5/8 | G9: 5 | H9: 1.77 | I9: =IF($F9=$I$6,$E9*$G9*$H9,"") | J9: =IF($F9=$J$6,$E9*$G9*$H9,"") | K9: =IF($F9=$K$6,$E9*$G9*$H9,"") | L9: =IF($F9=$L$6,$E9*$G9*$H9,"") | M9: =IF($F9=$M$6,$E9*$G9*$H9,"") -> 8.85 | N9: =IF($F9=$N$6,$E9*$G9*$H9,"") | O9: =IF($F9=$O$6,$E9*$G9*$H9,"") | P9: =IF($F9=$P$6,$E9*$G9*$H9,"")
C10: EJE Y | D10: KG | E10: 1 | F10: 5/8 | G10: 8 | H10: 1.27 | I10: =IF($F10=$I$6,$E10*$G10*$H10,"") | J10: =IF($F10=$J$6,$E10*$G10*$H10,"") | K10: =IF($F10=$K$6,$E10*$G10*$H10,"") | L10: =IF($F10=$L$6,$E10*$G10*$H10,"") | M10: =IF($F10=$M$6,$E10*$G10*$H10,"") -> 10.16 | N10: =IF($F10=$N$6,$E10*$G10*$H10,"") | O10: =IF($F10=$O$6,$E10*$G10*$H10,"") | P10: =IF($F10=$P$6,$E10*$G10*$H10,"")
B11: Z-2 | C11: EJE X | D11: KG | E11: 1 | F11: 5/8 | G11: 5 | H11: 2.37 | I11: =IF($F11=$I$6,$E11*$G11*$H11,"") | J11: =IF($F11=$J$6,$E11*$G11*$H11,"") | K11: =IF($F11=$K$6,$E11*$G11*$H11,"") | L11: =IF($F11=$L$6,$E11*$G11*$H11,"") | M11: =IF($F11=$M$6,$E11*$G11*$H11,"") -> 11.85 | N11: =IF($F11=$N$6,$E11*$G11*$H11,"") | O11: =IF($F11=$O$6,$E11*$G11*$H11,"") | P11: =IF($F11=$P$6,$E11*$G11*$H11,"")
C12: EJE Y | D12: KG | E12: 1 | F12: 5/8 | G12: 11 | H12: 1.27 | I12: =IF($F12=$I$6,$E12*$G12*$H12,"") | J12: =IF($F12=$J$6,$E12*$G12*$H12,"") | K12: =IF($F12=$K$6,$E12*$G12*$H12,"") | L12: =IF($F12=$L$6,$E12*$G12*$H12,"") | M12: =IF($F12=$M$6,$E12*$G12*$H12,"") -> 13.97 | N12: =IF($F12=$N$6,$E12*$G12*$H12,"") | O12: =IF($F12=$O$6,$E12*$G12*$H12,"") | P12: =IF($F12=$P$6,$E12*$G12*$H12,"")
B13: Z-3 | C13: EJE X | D13: KG | E13: 3 | F13: 5/8 | G13: 10 | H13: 1.27 | I13: =IF($F13=$I$6,$E13*$G13*$H13,"") | J13: =IF($F13=$J$6,$E13*$G13*$H13,"") | K13: =IF($F13=$K$6,$E13*$G13*$H13,"") | L13: =IF($F13=$L$6,$E13*$G13*$H13,"") | M13: =IF($F13=$M$6,$E13*$G13*$H13,"") -> 38.1 | N13: =IF($F13=$N$6,$E13*$G13*$H13,"") | O13: =IF($F13=$O$6,$E13*$G13*$H13,"") | P13: =IF($F13=$P$6,$E13*$G13*$H13,"")
C14: EJE Y | D14: KG | E14: 3 | F14: 5/8 | G14: 5 | H14: 2.27 | I14: =IF($F14=$I$6,$E14*$G14*$H14,"") | J14: =IF($F14=$J$6,$E14*$G14*$H14,"") | K14: =IF($F14=$K$6,$E14*$G14*$H14,"") | L14: =IF($F14=$L$6,$E14*$G14*$H14,"") | M14: =IF($F14=$M$6,$E14*$G14*$H14,"") -> 34.05 | N14: =IF($F14=$N$6,$E14*$G14*$H14,"") | O14: =IF($F14=$O$6,$E14*$G14*$H14,"") | P14: =IF($F14=$P$6,$E14*$G14*$H14,"")
B15: Z-4 | C15: EJE X | D15: KG | E15: 2 | F15: 5/8 | G15: 9 | H15: 1.37 | I15: =IF($F15=$I$6,$E15*$G15*$H15,"") | J15: =IF($F15=$J$6,$E15*$G15*$H15,"") | K15: =IF($F15=$K$6,$E15*$G15*$H15,"") | L15: =IF($F15=$L$6,$E15*$G15*$H15,"") | M15: =IF($F15=$M$6,$E15*$G15*$H15,"") -> 24.66 | N15: =IF($F15=$N$6,$E15*$G15*$H15,"") | O15: =IF($F15=$O$6,$E15*$G15*$H15,"") | P15: =IF($F15=$P$6,$E15*$G15*$H15,"")
C16: EJE Y | D16: KG | E16: 2 | F16: 5/8 | G16: 6 | H16: 2.07 | I16: =IF($F16=$I$6,$E16*$G16*$H16,"") | J16: =IF($F16=$J$6,$E16*$G16*$H16,"") | K16: =IF($F16=$K$6,$E16*$G16*$H16,"") | L16: =IF($F16=$L$6,$E16*$G16*$H16,"") | M16: =IF($F16=$M$6,$E16*$G16*$H16,"") -> 24.84 | N16: =IF($F16=$N$6,$E16*$G16*$H16,"") | O16: =IF($F16=$O$6,$E16*$G16*$H16,"") | P16: =IF($F16=$P$6,$E16*$G16*$H16,"")
B17: Z-5 | C17: EJE X | D17: KG | E17: 1 | F17: 5/8 | G17: 23 | H17: 1.27 | I17: =IF($F17=$I$6,$E17*$G17*$H17,"") | J17: =IF($F17=$J$6,$E17*$G17*$H17,"") | K17: =IF($F17=$K$6,$E17*$G17*$H17,"") | L17: =IF($F17=$L$6,$E17*$G17*$H17,"") | M17: =IF($F17=$M$6,$E17*$G17*$H17,"") -> 29.21 | N17: =IF($F17=$N$6,$E17*$G17*$H17,"") | O17: =IF($F17=$O$6,$E17*$G17*$H17,"") | P17: =IF($F17=$P$6,$E17*$G19*$H17,"")
C18: EJE Y | D18: KG | E18: 1 | F18: 5/8 | G18: 5 | H18: 4.77 | I18: =IF($F18=$I$6,$E18*$G18*$H18,"") | J18: =IF($F18=$J$6,$E18*$G18*$H18,"") | K18: =IF($F18=$K$6,$E18*$G18*$H18,"") | L18: =IF($F18=$L$6,$E18*$G18*$H18,"") | M18: =IF($F18=$M$6,$E18*$G18*$H18,"") -> 23.85 | N18: =IF($F18=$N$6,$E18*$G18*$H18,"") | O18: =IF($F18=$O$6,$E18*$G18*$H18,"") | P18: =IF($F18=$P$6,$E18*$G22*$H18,"")
B19: Z-6 (INFERIOR Y SUPERIOR) | C19: EJE X | D19: KG | E19: 1 | F19: 5/8 | G19: =2*20 -> 40 | H19: 2.37 | I19: =IF($F19=$I$6,$E19*$G19*$H19,"") | J19: =IF($F19=$J$6,$E19*$G19*$H19,"") | K19: =IF($F19=$K$6,$E19*$G19*$H19,"") | L19: =IF($F19=$L$6,$E19*$G19*$H19,"") | M19: =IF($F19=$M$6,$E19*$G19*$H19,"") -> 94.8 | N19: =IF($F19=$N$6,$E19*$G19*$H19,"") | O19: =IF($F19=$O$6,$E19*$G19*$H19,"") | P19: =IF($F19=$P$6,$E19*$G23*$H19,"")
C20: EJE Y | D20: KG | E20: 1 | F20: 3/4 | G20: =2*11 -> 22 | H20: 4.17 | I20: =IF($F20=$I$6,$E20*$G22*$H22,"") | J20: =IF($F20=$J$6,$E20*$G22*$H22,"") | K20: =IF($F20=$K$6,$E20*$G22*$H22,"") | L20: =IF($F20=$L$6,$E20*$G22*$H22,"") | M20: =IF($F20=$M$6,$E20*$G20*$H20,"") | N20: =IF($F20=$N$6,$E20*$G20*$H20,"") -> 91.74 | O20: =IF($F20=$O$6,$E20*$G22*$H22,"") | P20: =IF($F20=$P$6,$E20*$G24*$H22,"")
B21: Z-7 | C21: EJE X | D21: KG | E21: 1 | F21: 5/8 | G21: 7 | H21: 1.57 | I21: =IF($F21=$I$6,$E21*$G23*$H23,"") | J21: =IF($F21=$J$6,$E21*$G23*$H23,"") | K21: =IF($F21=$K$6,$E21*$G23*$H23,"") | L21: =IF($F21=$L$6,$E21*$G23*$H23,"") | M21: =IF($F21=$M$6,$E21*$G21*$H21,"") -> 10.99 | N21: =IF($F21=$N$6,$E21*$G21*$H21,"") | O21: =IF($F21=$O$6,$E21*$G23*$H23,"") | P21: =IF($F21=$P$6,$E21*#REF!*$H23,"")
C22: EJE Y | D22: KG | E22: 1 | F22: 5/8 | G22: 7 | H22: 1.67 | I22: =IF($F22=$I$6,$E22*$G24*$H24,"") | J22: =IF($F22=$J$6,$E22*$G24*$H24,"") | K22: =IF($F22=$K$6,$E22*$G24*$H24,"") | L22: =IF($F22=$L$6,$E22*$G24*$H24,"") | M22: =IF($F22=$M$6,$E22*$G22*$H22,"") -> 11.69 | N22: =IF($F22=$N$6,$E22*$G22*$H22,"") | O22: =IF($F22=$O$6,$E22*$G24*$H24,"") | P22: =IF($F22=$P$6,$E22*#REF!*$H24,"")
B23: Z-8 | C23: EJE X | D23: KG | E23: 1 | F23: 5/8 | G23: 24 | H23: 1.27 | I23: =IF($F23=$I$6,$E23*#REF!*#REF!,"") | J23: =IF($F23=$J$6,$E23*#REF!*#REF!,"") | K23: =IF($F23=$K$6,$E23*#REF!*#REF!,"") | L23: =IF($F23=$L$6,$E23*#REF!*#REF!,"") | M23: =IF($F23=$M$6,$E23*$G23*$H23,"") -> 30.48 | N23: =IF($F23=$N$6,$E23*$G23*$H23,"") | O23: =IF($F23=$O$6,$E23*#REF!*#REF!,"")
C24: EJE Y | D24: KG | E24: 1 | F24: 5/8 | G24: 5 | H24: 4.97 | I24: =IF($F24=$I$6,$E24*#REF!*#REF!,"") | J24: =IF($F24=$J$6,$E24*#REF!*#REF!,"") | K24: =IF($F24=$K$6,$E24*#REF!*#REF!,"") | L24: =IF($F24=$L$6,$E24*#REF!*#REF!,"") | M24: =IF($F24=$M$6,$E24*$G24*$H24,"") -> 24.85 | N24: =IF($F24=$N$6,$E24*$G24*$H24,"") | O24: =IF($F24=$O$6,$E24*#REF!*#REF!,"")
B25: Z-9 | C25: EJE X | D25: KG | E25: 1 | F25: 5/8 | G25: 23 | H25: 1.57 | I25: =IF($F25=$I$6,$E25*$G25*$H25,"") | J25: =IF($F25=$J$6,$E25*$G25*$H25,"") | K25: =IF($F25=$K$6,$E25*$G25*$H25,"") | L25: =IF($F25=$L$6,$E25*$G25*$H25,"") | M25: =IF($F25=$M$6,$E25*$G25*$H25,"") -> 36.11 | N25: =IF($F25=$N$6,$E25*$G25*$H25,"") | O25: =IF($F25=$O$6,$E25*$G25*$H25,"")
C26: EJE Y | D26: KG | E26: 1 | F26: 5/8 | G26: 7 | H26: 4.87 | I26: =IF($F26=$I$6,$E26*$G26*$H26,"") | J26: =IF($F26=$J$6,$E26*$G26*$H26,"") | K26: =IF($F26=$K$6,$E26*$G26*$H26,"") | L26: =IF($F26=$L$6,$E26*$G26*$H26,"") | M26: =IF($F26=$M$6,$E26*$G26*$H26,"") -> 34.09 | N26: =IF($F26=$N$6,$E26*$G26*$H26,"") | O26: =IF($F26=$O$6,$E26*$G26*$H26,"")
B27: CIMIENTO TABIQUERIA | C27: EJE X | D27: KG | E27: 1 | F27: 3/8 | G27: 44 | H27: 1.5 | I27: =IF($F27=$I$6,$E27*$G27*$H27,"") | J27: =IF($F27=$J$6,$E27*$G27*$H27,"") | K27: =IF($F27=$K$6,$E27*$G27*$H27,"") -> 66 | L27: =IF($F27=$L$6,$E27*$G27*$H27,"") | M27: =IF($F27=$M$6,$E27*$G27*$H27,"") | N27: =IF($F27=$N$6,$E27*$G27*$H27,"") | O27: =IF($F27=$O$6,$E27*$G27*$H27,"")
C28: EJE Y | D28: KG | E28: 1 | F28: 3/8 | G28: 2 | H28: 13.05 | I28: =IF($F28=$I$6,$E28*$G28*$H28,"") | J28: =IF($F28=$J$6,$E28*$G28*$H28,"") | K28: =IF($F28=$K$6,$E28*$G28*$H28,"") -> 26.1 | L28: =IF($F28=$L$6,$E28*$G28*$H28,"") | M28: =IF($F28=$M$6,$E28*$G28*$H28,"") | N28: =IF($F28=$N$6,$E28*$G28*$H28,"") | O28: =IF($F28=$O$6,$E28*$G28*$H28,"")
N29: =IF($F29=$N$6,$E29*$G29*$H29,"")
G30: LONGITUD TOTAL | I30: =SUM(I9:I29) -> 0 | J30: =SUM(J9:J29) -> 0 | K30: =SUM(K9:K29) -> 92.1 | L30: =SUM(L9:L29) -> 0 | M30: =SUM(M9:M29) -> 462.55 | N30: =SUM(N9:N29) -> 91.74 | O30: =SUM(O9:O29) -> 0
G31: PESO UNITARIO | I31: 0.21 | J31: 0.38 | K31: 0.53 | L31: 0.94 | M31: 1.46 | N31: 2.11 | O31: 3.74
G32: PESO TOTAL | I32: =I30*I31 -> 0 | J32: =J30*J31 -> 0 | K32: =K30*K31 -> 48.813 | L32: =L30*L31 -> 0 | M32: =M30*M31 -> 675.323 | N32: =N30*N31 -> 193.5714 | O32: =O30*O31 -> 0
G33: # DE VARILLA | I33: =ROUNDUP(I30*1.07/9,0) -> 0 | J33: =ROUNDUP(J30*1.07/9,0) -> 0 | K33: =ROUNDUP(K30*1.07/9,0) -> 11 | L33: =ROUNDUP(L30*1.07/9,0) -> 0 | M33: =ROUNDUP(M30*1.07/9,0) -> 55 | N33: =ROUNDUP(N30*1.07/9,0) -> 11 | O33: =ROUNDUP(O30*1.07/9,0) -> 0
A34: 01.01.00 | B34: ACERO ASTM f'y = 4200 kg/cm2 EN VIGAS DE CIMENTACION | P34: =SUM(I46:O46) -> 855.2704
B35: VC-1 | I35: =IF($F35=$I$6,$E35*$G35*$H35,"") | J35: =IF($F35=$J$6,$E35*$G35*$H35,"") | K35: =IF($F35=$K$6,$E35*$G35*$H35,"") | L35: =IF($F35=$L$6,$E35*$G35*$H35,"") | M35: =IF($F35=$M$6,$E35*$G35*$H35,"") | N35: =IF($F35=$N$6,$E35*$G35*$H35,"") | O35: =IF($F35=$O$6,$E35*$G35*$H35,"")
B36: ACE. SUPERIOR | D36: KG | E36: 5 | F36: 3/4 | G36: 4 | H36: 5.44 | I36: =IF($F36=$I$6,$E36*$G36*$H36,"") | J36: =IF($F36=$J$6,$E36*$G36*$H36,"") | K36: =IF($F36=$K$6,$E36*$G36*$H36,"") | L36: =IF($F36=$L$6,$E36*$G36*$H36,"") | M36: =IF($F36=$M$6,$E36*$G36*$H36,"") | N36: =IF($F36=$N$6,$E36*$G36*$H36,"") -> 108.8 | O36: =IF($F36=$O$6,$E36*$G36*$H36,"")
B37: ACE. INFERIOR | D37: KG | E37: 5 | F37: 3/4 | G37: 3 | H37: 5.44 | I37: =IF($F37=$I$6,$E37*$G37*$H37,"") | J37: =IF($F37=$J$6,$E37*$G37*$H37,"") | K37: =IF($F37=$K$6,$E37*$G37*$H37,"") | L37: =IF($F37=$L$6,$E37*$G37*$H37,"") | M37: =IF($F37=$M$6,$E37*$G37*$H37,"") | N37: =IF($F37=$N$6,$E37*$G37*$H37,"") -> 81.6 | O37: =IF($F37=$O$6,$E37*$G37*$H37,"")
B38: ESTRIBOS | D38: KG | E38: 5 | F38: 3/8 | G38: 38 | H38: 1.34 | I38: =IF($F38=$I$6,$E38*$G38*$H38,"") | J38: =IF($F38=$J$6,$E38*$G38*$H38,"") | K38: =IF($F38=$K$6,$E38*$G38*$H38,"") -> 254.6 | L38: =IF($F38=$L$6,$E38*$G38*$H38,"") | M38: =IF($F38=$M$6,$E38*$G38*$H38,"") | N38: =IF($F38=$N$6,$E38*$G38*$H38,"") | O38: =IF($F38=$O$6,$E38*$G38*$H38,"")
B39: VC-2 | I39: =IF($F39=$I$6,$E39*$G39*$H39,"") | J39: =IF($F39=$J$6,$E39*$G39*$H39,"") | K39: =IF($F39=$K$6,$E39*$G39*$H39,"") | L39: =IF($F39=$L$6,$E39*$G39*$H39,"") | M39: =IF($F39=$M$6,$E39*$G39*$H39,"") | N39: =IF($F39=$N$6,$E39*$G39*$H39,"") | O39: =IF($F39=$O$6,$E39*$G39*$H39,"")
B40: ACE. SUPERIOR | D40: KG | E40: 2 | F40: 3/4 | G40: 5 | H40: 5.44 | I40: =IF($F40=$I$6,$E40*$G40*$H40,"") | J40: =IF($F40=$J$6,$E40*$G40*$H40,"") | K40: =IF($F40=$K$6,$E40*$G40*$H40,"") | L40: =IF($F40=$L$6,$E40*$G40*$H40,"") | M40: =IF($F40=$M$6,$E40*$G40*$H40,"") | N40: =IF($F40=$N$6,$E40*$G40*$H40,"") -> 54.4 | O40: =IF($F40=$O$6,$E40*$G40*$H40,"")
...

Sheet O. HUMEDAD
A2: =Valorización!A2 -> PROYECTO: | B2: =Valorización!B2 -> 0
A3: =Valorización!A3 -> PROPIETARIO(S) : | B3: =Valorización!B3 -> 0
A4: =Valorización!A4 -> UBICACIÓN: | B4: LT 18 MZ DDF, JR. ALAMEDA EL ESPINEL, URB BRISAS DEL MAR - DISTRITO CHORRILLOS, DEPARTAMENTO Y PROVINCIA DE LIMA
A5: PARTIDA | B5: DESCRIPCION | D5: und | E5: CANT | F5: MEDIDAS | I5: PARCIAL
F6: LARGO | G6: ANCHO | H6: ALTO
A7: 03.00.00.00 | B7: TABIQUERIA Y OBRAS HÚMEDAS
A8: 03.00.00.00 | B8: 1ER PISO
A9: 03.01.01.00 | B9: TABIQUE DE LADRILLO
A10: 03.03.01.01 | B10: MURO DE LADRILLO SOGA PANDERETA | D10: M2 | J10: =SUM(I11:I23) -> 92.25
B11: MURO 1 | D11: m2 | E11: 1 | F11: 2.2 | H11: 3 | I11: =PRODUCT(E11:H11) -> 6.6
B12: MURO 2 | D12: m2 | E12: 1 | F12: 3.95 | H12: 3 | I12: =PRODUCT(E12:H12) -> 11.85
B13: MURO 3 | D13: m2 | E13: 1 | F13: 2.2 | H13: 3 | I13: =PRODUCT(E13:H13) -> 6.6
B14: MURO 4 | D14: m2 | E14: 1 | F14: 1.8 | H14: 3 | I14: =PRODUCT(E14:H14) -> 5.4
B15: MURO 5 | D15: m2 | E15: 1 | F15: 1.2 | H15: 3 | I15: =PRODUCT(E15:H15) -> 3.6
B16: MURO 6 | D16: m2 | E16: 1 | F16: 0.65 | H16: 3 | I16: =PRODUCT(E16:H16) -> 1.95
B17: MURO 7 | D17: m2 | E17: 1 | F17: 2.4 | H17: 3 | I17: =PRODUCT(E17:H17) -> 7.2
B18: MURO 8 | D18: m2 | E18: 1 | F18: 2.95 | H18: 3 | I18: =PRODUCT(E18:H18) -> 8.85
B19: MURO 9 | D19: m2 | E19: 1 | F19: 3.2 | H19: 3 | I19: =PRODUCT(E19:H19) -> 9.6
B20: MURO 10 | D20: m2 | E20: 1 | F20: 5.45 | H20: 3 | I20: =PRODUCT(E20:H20) -> 16.35
B21: MURO 11 | D21: m2 | E21: 1 | F21: 1.25 | H21: 3 | I21: =PRODUCT(E21:H21) -> 3.75
B22: MURO 12 | D22: m2 | E22: 1 | F22: 3.5 | H22: 3 | I22: =PRODUCT(E22:H22) -> 10.5
A24: 03.03.01.01 | B24: COLUMNETAS | D24: UND | J24: =SUM(I25:I25) -> 12
B25: Ca | D25: UND | E25: 12 | I25: =PRODUCT(E25:H25) -> 12
A27: 02.03.02.00 | B27: REVESTIMIENTOS Y ENLUCIDOS
A28: 02.03.02.01 | B28: TARRAJEO EN INTERIORES FROTACHADO | D28: M2 | J28: =SUM(I29:I41) -> 184.5
B29: MURO 1 | D29: m2 | E29: 2 | F29: 2.2 | H29: 3 | I29: =PRODUCT(E29:H29) -> 13.2
B30: MURO 2 | D30: m2 | E30: 2 | F30: 3.95 | H30: 3 | I30: =PRODUCT(E30:H30) -> 23.7
B31: MURO 3 | D31: m2 | E31: 2 | F31: 2.2 | H31: 3 | I31: =PRODUCT(E31:H31) -> 13.2
B32: MURO 4 | D32: m2 | E32: 2 | F32: 1.8 | H32: 3 | I32: =PRODUCT(E32:H32) -> 10.8
B33: MURO 5 | D33: m2 | E33: 2 | F33: 1.2 | H33: 3 | I33: =PRODUCT(E33:H33) -> 7.2
B34: MURO 6 | D34: m2 | E34: 2 | F34: 0.65 | H34: 3 | I34: =PRODUCT(E34:H34) -> 3.9
B35: MURO 7 | D35: m2 | E35: 2 | F35: 2.4 | H35: 3 | I35: =PRODUCT(E35:H35) -> 14.4
B36: MURO 8 | D36: m2 | E36: 2 | F36: 2.95 | H36: 3 | I36: =PRODUCT(E36:H36) -> 17.7
B37: MURO 9 | D37: m2 | E37: 2 | F37: 3.2 | H37: 3 | I37: =PRODUCT(E37:H37) -> 19.2
B38: MURO 10 | D38: m2 | E38: 2 | F38: 5.45 | H38: 3 | I38: =PRODUCT(E38:H38) -> 32.7
B39: MURO 11 | D39: m2 | E39: 2 | F39: 1.25 | H39: 3 | I39: =PRODUCT(E39:H39) -> 7.5
B40: MURO 12 | D40: m2 | E40: 2 | F40: 3.5 | H40: 3 | I40: =PRODUCT(E40:H40) -> 21
A42: 02.03.02.04 | B42: TARRAJEO EN COLUMNAS Y PLACAS | D42: M2 | J42: =SUM(I43:I71) -> 96.752
B43: C-1 | D43: m2 | E43: 1 | F43: PERIM = | G43: 0.9 | H43: 3 | I43: =PRODUCT(E43:H43) -> 2.7
B44: C-2 | D44: m2 | E44: 1 | F44: PERIM = | G44: 1.15 | H44: 3 | I44: =PRODUCT(E44:H44) -> 3.45
...

Sheet APUs Casco
A2: OBRAS PRELIMINARES
A3: TRANSPORTE DE EQUIPOS Y HERRAMIENTAS | E3: CU | F3: =F6+F8 -> 2000
A4: RENDIMIENTO | B4: 1 | C4: GLB/d | D4: JORNADA | E4: 8 | F4: horas/dia
A5: Descripción de Recurso | B5: Unidad | C5: Cuadrilla | D5: Cantidad | E5: Precio (S/.) | F5: Parcial (S/.)
A6: MANO DE OBRA | F6: =SUM(F7) -> 1800
A7: MANO DE OBRA- T | B7: GLB | D7: 1 | E7: 1800 | F7: =PRODUCT(D7:E7) -> 1800
A8: EQUIPOS | F8: =SUM(F9) -> 200
A9: HERRAMIENTA-T | B9: GLB | D9: 1 | E9: 200 | F9: =PRODUCT(D9:E9) -> 200
A11: LIMPIEZA DE TERRENO MANUAL | E11: CU | F11: =F14+F17 -> 7.3422222
A12: RENDIMIENTO | B12: 75 | C12: m2/d | D12: JORNADA | E12: 8 | F12: horas/dia
A13: Descripción de Recurso | B13: Unidad | C13: Cuadrilla | D13: Cantidad | E13: Precio (S/.) | F13: Parcial (S/.)
A14: MANO DE OBRA | F14: =SUM(F15:F16) -> 1.8355556
A15: CAPATAZ | B15: hh | C15: 0.1 | D15: =C15*$E$12/$B$12 -> 0.010666667 | E15: =VLOOKUP(A15,INSUMOS!$B$7:$D$42,3,0) -> 49.166667 | F15: =PRODUCT(D15:E15) -> 0.52444444
A16: PEON | B16: hh | C16: 1 | D16: =C16*$E$12/$B$12 -> 0.10666667 | E16: =VLOOKUP(A16,INSUMOS!$B$7:$D$42,3,0) -> 12.291667 | F16: =PRODUCT(D16:E16) -> 1.3111111
A17: EQUIPOS | F17: =SUM(F18) -> 5.5066667
A18: HERRAMIENTAS MANUALES | B18: %mo | D18: 3 | E18: =+F14 -> 1.8355556 | F18: =PRODUCT(D18:E18) -> 5.5066667
A20: TRAZADO Y REPLANTEO S/EQUIPO | E20: CU | F20: =F23+F27+F31 -> 9.9761117
A21: RENDIMIENTO | B21: 80 | C21: m2/d | D21: JORNADA | E21: 8 | F21: horas/dia
A22: Descripción de Recurso | B22: Unidad | C22: Cuadrilla | D22: Cantidad | E22: Precio (S/.) | F22: Parcial (S/.)
A23: MANO DE OBRA | F23: =SUM(F24:F26) -> 8.6981667
A24: CAPATAZ | B24: hh | C24: 0.1 | D24: =C24*$E$21/$B$21 -> 0.01 | E24: =VLOOKUP(A24,INSUMOS!$B$7:$D$42,3,0) -> 49.166667 | F24: =PRODUCT(D24:E24) -> 0.49166667
A25: OPERARIO | B25: hh | C25: 3 | D25: =C25*$E$21/$B$21 -> 0.3 | E25: =VLOOKUP(A25,INSUMOS!$B$7:$D$42,3,0) -> 27.041667 | F25: =PRODUCT(D25:E25) -> 8.1125
A26: MADERA TORNILLO | B26: p2 | D26: 0.02 | E26: 4.7 | F26: =PRODUCT(D26:E26) -> 0.094
A27: MATERIALES | F27: =SUM(F28:F30) -> 1.017
A28: CLAVOS CON CABEZA | B28: kg | D28: 0.01 | E28: 2.9 | F28: =PRODUCT(D28:E28) -> 0.029
A29: CAL (BOLSA x 20kg) | B29: bl | D29: 0.1 | E29: 9.5 | F29: =PRODUCT(D29:E29) -> 0.95
A30: CORDEL | B30: m | D30: 0.19 | E30: 0.2 | F30: =PRODUCT(D30:E30) -> 0.038
A31: EQUIPOS | F31: =SUM(F32) -> 0.260945
A32: HERRAMIENTAS MANUALES | B32: %mo | D32: 3 | E32: =F23 -> 8.6981667 | F32: =D32*E32/100 -> 0.260945
A34: TRAZADO Y REPLANTEO C/EQUIPO | E34: CU | F34: =F37+F41+F45 -> 15.196667
A35: RENDIMIENTO | B35: 50 | C35: m2/d | D35: JORNADA | E35: 8 | F35: horas/dia
A36: Descripción de Recurso | B36: Unidad | C36: Cuadrilla | D36: Cantidad | E36: Precio (S/.) | F36: Parcial (S/.)
A37: MANO DE OBRA | F37: =SUM(F38:F40) -> 13.766667
A38: CAPATAZ | B38: hh | C38: 0.1 | D38: =C38*$E$35/$B$35 -> 0.016 | E38: =VLOOKUP(A38,INSUMOS!$B$7:$D$42,3,0) -> 49.166667 | F38: =PRODUCT(D38:E38) -> 0.78666667
A39: OPERARIO | B39: hh | C39: 3 | D39: =C39*$E$35/$B$35 -> 0.48 | E39: =VLOOKUP(A39,INSUMOS!$B$7:$D$42,3,0) -> 27.041667 | F39: =PRODUCT(D39:E39) -> 12.98
A40: MADERA TORNILLO | B40: p2 | D40: =C40*$E$35/$B$35 -> 0 | E40: 4.7 | F40: =PRODUCT(D40:E40) -> 0
A41: MATERIALES | F41: =SUM(F42:F44) -> 1.017
A42: CLAVOS CON CABEZA | B42: kg | D42: 0.01 | E42: 2.9 | F42: =PRODUCT(D42:E42) -> 0.029
A43: CAL (BOLSA x 20kg) | B43: bl | D43: 0.1 | E43: 9.5 | F43: =PRODUCT(D43:E43) -> 0.95
A44: CORDEL | B44: m | D44: 0.19 | E44: 0.2 | F44: =PRODUCT(D44:E44) -> 0.038
...

Sheet RESUMEN
B1: PRESUPUESTO DE OBRA | D1: VALORIZACIONES | L1: VALORIZACIONES | T1: VALORIZACIONES | AB1: VALORIZACIONES
B2: DESCRIPCIÓN DE PARTIDAS | C2: MONTO | D2: semana 01 | F2: semana 02 | H2: semana 03 | J2: semana 04 | L2: semana 05 | N2: semana 06 | P2: semana 07 | R2: semana 08 | T2: semana 09 | V2: semana 10 | X2: semana 11 | Z2: semana 12 | AB2: semana 13 | AD2: semana 14 | AF2: semana 15 | AH2: semana 16
B3: OBRAS PRELIMINARES Y MOVIMIENTO DE TIERRAS | C3: =SUM(C4:C7) -> 54537.403 | E3: =SUM(E4:E7) -> 16611.609 | G3: =SUM(G4:G7) -> 19465.501 | I3: =SUM(I4:I7) -> 12893.808 | K3: =SUM(K4:K7) -> 0 | M3: =SUM(M4:M7) -> 1855.4946 | O3: =SUM(O4:O7) -> 0 | Q3: =SUM(Q4:Q7) -> 0 | S3: =SUM(S4:S7) -> 0 | U3: =SUM(U4:U7) -> 1855.4946 | W3: =SUM(W4:W7) -> 0 | Y3: =SUM(Y4:Y7) -> 0 | AA3: =SUM(AA4:AA7) -> 0 | AC3: =SUM(AC4:AC7) -> 1855.4946 | AE3: =SUM(AE4:AE7) -> 0 | AG3: =SUM(AG4:AG7) -> 0 | AI3: =SUM(AI4:AI7) -> 0
A4: =+D4+F4+H4+J4+L4+N4+P4+R4+T4+V4+X4+Z4+AB4+AD4+AF4+AH4 -> 1 | B4: OBRAS PRELIMINARES | C4: 10876.107 | D4: 0.7 | E4: =+C4*D4 -> 7613.2747 | F4: 0.3 | G4: =+C4*F4 -> 3262.832 | H4: 0 | I4: =+C4*H4 -> 0 | J4: 0 | K4: =+C4*J4 -> 0 | L4: 0 | M4: =+L4*C4 -> 0 | N4: 0 | O4: =+N4*C4 -> 0 | P4: 0 | Q4: =+P4*C4 -> 0 | R4: 0 | S4: =+R4*C4 -> 0 | T4: 0 | U4: =+C4*T4 -> 0 | V4: 0 | W4: =+C4*V4 -> 0 | X4: 0 | Y4: =+C4*X4 -> 0 | Z4: 0 | AA4: =+C4*Z4 -> 0 | AB4: 0 | AC4: =+C4*AB4 -> 0 | AD4: 0 | AE4: =+C4*AD4 -> 0 | AF4: 0 | AG4: =+C4*AF4 -> 0 | AH4: 0 | AI4: =+AH4*C4 -> 0
A5: =+D5+F5+H5+J5+L5+N5+P5+R5+T5+V5+X5+Z5+AB5+AD5+AF5+AH5 -> 1 | B5: DEMOLICIÓN PARCIAL | C5: 28571.36 | D5: 0.25 | E5: =+C5*D5 -> 7142.84 | F5: 0.5 | G5: =+C5*F5 -> 14285.68 | H5: 0.25 | I5: =+C5*H5 -> 7142.84 | J5: 0 | K5: =+C5*J5 -> 0 | L5: 0 | M5: =+L5*C5 -> 0 | N5: 0 | O5: =+N5*C5 -> 0 | P5: 0 | Q5: =+P5*C5 -> 0 | R5: 0 | S5: =+R5*C5 -> 0 | T5: 0 | U5: =+C5*T5 -> 0 | V5: 0 | W5: =+C5*V5 -> 0 | X5: 0 | Y5: =+C5*X5 -> 0 | Z5: 0 | AA5: =+C5*Z5 -> 0 | AB5: 0 | AC5: =+C5*AB5 -> 0 | AD5: 0 | AE5: =+C5*AD5 -> 0 | AF5: 0 | AG5: =+C5*AF5 -> 0 | AH5: 0 | AI5: =+AH5*C5 -> 0
A6: =+D6+F6+H6+J6+L6+N6+P6+R6+T6+V6+X6+Z6+AB6+AD6+AF6+AH6 -> 1 | B6: MOVIMIENTO DE TIERRAS | C6: 7667.9579 | D6: 0 | E6: =+C6*D6 -> 0 | F6: 0.25 | G6: =+C6*F6 -> 1916.9895 | H6: 0.75 | I6: =+C6*H6 -> 5750.9684 | J6: 0 | K6: =+C6*J6 -> 0 | L6: 0 | M6: =+L6*C6 -> 0 | N6: 0 | O6: =+N6*C6 -> 0 | P6: 0 | Q6: =+P6*C6 -> 0 | R6: 0 | S6: =+R6*C6 -> 0 | T6: 0 | U6: =+C6*T6 -> 0 | V6: 0 | W6: =+C6*V6 -> 0 | X6: 0 | Y6: =+C6*X6 -> 0 | Z6: 0 | AA6: =+C6*Z6 -> 0 | AB6: 0 | AC6: =+C6*AB6 -> 0 | AD6: 0 | AE6: =+C6*AD6 -> 0 | AF6: 0 | AG6: =+C6*AF6 -> 0 | AH6: 0 | AI6: =+AH6*C6 -> 0
A7: =+D7+F7+H7+J7+L7+N7+P7+R7+T7+V7+X7+Z7+AB7+AD7+AF7+AH7 -> 1 | B7: SEGURIDAD Y SALUD | C7: 7421.9785 | D7: 0.25 | E7: =+C7*D7 -> 1855.4946 | F7: 0 | G7: =+C7*F7 -> 0 | H7: 0 | I7: =+C7*H7 -> 0 | J7: 0 | K7: =+C7*J7 -> 0 | L7: 0.25 | M7: =+L7*C7 -> 1855.4946 | N7: 0 | O7: =+N7*C7 -> 0 | P7: 0 | Q7: =+P7*C7 -> 0 | R7: 0 | S7: =+R7*C7 -> 0 | T7: 0.25 | U7: =+C7*T7 -> 1855.4946 | V7: 0 | W7: =+C7*V7 -> 0 | X7: 0 | Y7: =+C7*X7 -> 0 | Z7: 0 | AA7: =+C7*Z7 -> 0 | AB7: 0.25 | AC7: =+C7*AB7 -> 1855.4946 | AD7: 0 | AE7: =+C7*AD7 -> 0 | AF7: 0 | AG7: =+C7*AF7 -> 0 | AH7: 0 | AI7: =+AH7*C7 -> 0
B8: 1 ER PISO | C8: =SUM(C9:C14) -> 129861.17 | E8: =SUM(E9:E14) -> 0 | G8: =SUM(G9:G14) -> 0 | I8: =SUM(I9:I14) -> 8223.1862 | K8: =SUM(K9:K14) -> 21614.506 | M8: =SUM(M9:M14) -> 20910.146 | O8: =SUM(O9:O14) -> 8066.1912 | Q8: =SUM(Q9:Q14) -> 13234.325 | S8: =SUM(S9:S14) -> 0 | U8: =SUM(U9:U14) -> 5683.1674 | W8: =SUM(W9:W14) -> 11307.684 | Y8: =SUM(Y9:Y14) -> 11307.684 | AA8: =SUM(AA9:AA14) -> 11640.946 | AC8: =SUM(AC9:AC14) -> 5957.7786 | AE8: =SUM(AE9:AE14) -> 5957.7786 | AG8: =SUM(AG9:AG14) -> 5957.7786 | AI8: =SUM(AI9:AI14) -> 0
A9: =+D9+F9+H9+J9+L9+N9+P9+R9+T9+V9+X9+Z9+AB9+AD9+AF9+AH9 -> 1 | B9: OBRAS DE CONCRETO SIMPLE | C9: 17227.114 | D9: 0 | E9: =+C9*D9 -> 0 | F9: 0 | G9: =+C9*F9 -> 0 | H9: 0 | I9: =+C9*H9 -> 0 | J9: 0.3 | K9: =+C9*J9 -> 5168.1341 | L9: 0.1 | M9: =+L9*C9 -> 1722.7114 | N9: 0.15 | O9: =+N9*C9 -> 2584.067 | P9: 0.45 | Q9: =+P9*C9 -> 7752.2011 | R9: 0 | S9: =+R9*C9 -> 0 | T9: 0 | U9: =+C9*T9 -> 0 | V9: 0 | W9: =+C9*V9 -> 0 | X9: 0 | Y9: =+C9*X9 -> 0 | Z9: 0 | AA9: =+C9*Z9 -> 0 | AB9: 0 | AC9: =+C9*AB9 -> 0 | AD9: 0 | AE9: =+C9*AD9 -> 0 | AF9: 0 | AG9: =+C9*AF9 -> 0 | AH9: 0 | AI9: =+AH9*C9 -> 0
